i will get you some logs to make you understand 
errors:

[2025-07-06 19:06:00] Loaded TALLY_URL: http://localhost:9000
[2025-07-06 19:06:59] Sync Data button clicked.
[2025-07-06 19:06:59] Sending test connection POST to http://localhost:9000
[2025-07-06 19:07:24] Test connection response: status=200, text=<ENVELOPE>

 <HEADER>

  <TALLYREQUEST>Import Data</TALLYREQUEST>

 </HEADER>

 <BODY>

  <IMPORTDATA>

   <REQUESTDESC>

    <REPORTNAME>All Masters</REPORTNAME>

    <STATICVARIABLES>

     <SVCURRE
[2025-07-06 19:07:25] Tally connected. Fetching data...
[2025-07-06 19:07:25] Sending data request to http://localhost:9000 with XML: 
    <ENVELOPE>
        <HEADER>
            <TALLYREQUEST>Export Data</TALLYREQUEST>
        </HEAD
[2025-07-06 19:07:32] Data request response: status=200, text=<ENVELOPE>

 <VOUCHERDATE></VOUCHERDATE>

 <VOUCHERTYPE>Sales</VOUCHERTYPE>

 <VOUCHERNUMBER>24-25/01</VOUCHERNUMBER>

 <PARTYNAME>BHS-SONTHOFEN INDIA PRIVATE LIMITED</PARTYNAME>

 <VOUCHERAMOUNT>10,6
[2025-07-06 19:07:32] ❌ Failed to parse Tally XML: reference to invalid character number: line 39271, column 14
Response: <ENVELOPE>

 <VOUCHERDATE></VOUCHERDATE>

 <VOUCHERTYPE>Sales</VOUCHERTYPE>

 <VOUCHERNUMBER>24-25/01</VOUCHERNUMBER>

 <PARTYNAME>BHS-SONTHOFEN INDIA PRIVATE LIMITED</PARTYNAME>

 <VOUCHERAMOUNT>10,67,900.00</VOUCHERAMOUNT>

 <VOUCHERDATE></VOUCHERDATE>

 <VOUCHERTYPE>Sales</VOUCHERTYPE>

 <VOUCHERNUMBER>24-25/02</VOUCHERNUMBER>

 <PARTYNAME>BHS-SONTHOFEN INDIA PRIVATE LIMITED</PARTYNAME>

 <VOUCHERAMOUNT>15,659.00</VOUCHERAMOUNT>

 <VOUCHERDATE></VOUCHERDATE>

 <VOUCHERTYPE>Sales</VOUCHERTYPE>

 <VOUCHERNUMBER>24-25/03</VOUCHERNUMBER>

 <PARTYNAME>KPS Automation</PARTYNAME>

 <VOUCHERAMOUNT>64,900.00</VOUCHERAMOUNT>

 <VOUCHERDATE></VOUCHERDATE>

 <VOUCHERTYPE>Sales</VOUCHERTYPE>

 <VOUCHERNUMBER>24-25/04</VOUCHERNUMBER>

 <PARTYNAME>Balaji Amines Limited</PARTYNAME>

 <VOUCHERAMOUNT>7,462.00</VOUCHERAMOUNT>

 <VOUCHERDATE></VOUCHERDATE>

 <VOUCHERTYPE>Payment</VOUCHERTYPE>

 <VOUCHERNUMBER>PMT/1</VOUCHERNUMBER>

 <PARTYNAME>V-Trans&#13;&#10;</PARTYNAME>

 <VOUCHERAMOUNT>1,360.00</VOUCHERAMOUNT>

 <VOUCHERDATE></VOUCHERDATE>

 <VOUCHERTYPE>Payment</VOUCHERTYPE>

 <VOUCHERNUMBER>PMT/2</VOUCHERNUMBER>

 <PARTYNAME>V-Trans&#13;&#10;</PARTYNAME>

 <VOUCHERAMOUNT>1,500.00</VOUCHERAMOUNT>

 <VOUCHERDATE></VOUCHERDATE>

 <VOUCHERTYPE>Purchase</VOUCHERTYPE>

 <VOUCHERNUMBER>JODLMH0424/0119</VOUCHERNUMBER>

 <PARTYNAME>JSW One Distribution Limited</PARTYNAME>

 <VOUCHERAMOUNT>3,59,853.00</VOUCHERAMOUNT>

 <VOUCHERDATE></VOUCHERDATE>

 <VOUCHERTYPE>Purchase</VOUCHERTYPE>

 <VOUCHERNUMBER>JODLMH0424/0120</VOUCHERNUMBER>

 <PARTYNAME>JSW One Distribution Limited</PARTYNAME>

 <VOUCHERAMOUNT>10,231.00</VOUCHERAMOUNT>

 <VOUCHERDATE></VOUCHERDATE>


PENING>0.00</LEDGEROPENING>

 <LEDGERNAMEEXPORT>Zuventus HealthCare Limited</LEDGERNAMEEXPORT>

 <LEDGERGROUP>Sundry Debtors - Raw Material</LEDGERGROUP>

 <LEDGEROPENING>0.00</LEDGEROPENING>

 <LEDGERNAMEEXPORT>ZYDEX INDUSTRIES</LEDGERNAMEEXPORT>

 <LEDGERGROUP>Sundry Creditors for Raw Materil</LEDGERGROUP>

 <LEDGEROPENING>0.00</LEDGEROPENING>

 <LEDGERNAMEEXPORT>ZYDEX INDUSTRIES PRIVATE LIMITED</LEDGERNAMEEXPORT>

 <LEDGERGROUP>Sundry Debtors - Raw Material</LEDGERGROUP>

 <LEDGEROPENING>0.00</LEDGEROPENING>

 <LEDGERNAMEEXPORT>Zydex Industries Pvt.Ltd</LEDGERNAMEEXPORT>

 <LEDGERGROUP>Sundry Creditors for Raw Materil</LEDGERGROUP>

 <LEDGEROPENING>0.00</LEDGEROPENING>

 <LEDGERNAMEEXPORT>?VENUGOPAL FOODS PVT. LTD</LEDGERNAMEEXPORT>

 <LEDGERGROUP>Sundry Debtors - Raw Material</LEDGERGROUP>

 <LEDGEROPENING>0.00</LEDGEROPENING>

</ENVELOPE>


[2025-07-06 19:07:52] No data fetched from Tally.
[2025-07-06 20:34:26] Loaded TALLY_URL: http://localhost:9000
[2025-07-06 20:34:29] Sync Data button clicked.
[2025-07-06 20:34:29] Sending test connection POST to http://localhost:9000
[2025-07-06 20:37:04] ❌ Connection failed: HTTPConnectionPool(host='localhost', port=9000): Read timed out. (read timeout=150)
Traceback (most recent call last):
  File "C:\Users\Admin\Nilesh_Projects\CFA\cfa_ai_app\backend\venv\Lib\site-packages\urllib3\connectionpool.py", line 534, in _make_request
    response = conn.getresponse()
  File "C:\Users\Admin\Nilesh_Projects\CFA\cfa_ai_app\backend\venv\Lib\site-packages\urllib3\connection.py", line 565, in getresponse
    httplib_response = super().getresponse()
  File "C:\Users\Admin\AppData\Local\Programs\Python\Python313\Lib\http\client.py", line 1430, in getresponse
    response.begin()
    ~~~~~~~~~~~~~~^^
  File "C:\Users\Admin\AppData\Local\Programs\Python\Python313\Lib\http\client.py", line 331, in begin
    version, status, reason = self._read_status()
                              ~~~~~~~~~~~~~~~~~^^
  File "C:\Users\Admin\AppData\Local\Programs\Python\Python313\Lib\http\client.py", line 292, in _read_status
    line = str(self.fp.readline(_MAXLINE + 1), "iso-8859-1")
               ~~~~~~~~~~~~~~~~^^^^^^^^^^^^^^
  File "C:\Users\Admin\AppData\Local\Programs\Python\Python313\Lib\socket.py", line 719, in readinto
    return self._sock.recv_into(b)
           ~~~~~~~~~~~~~~~~~~~~^^^
TimeoutError: timed out

The above exception was the direct cause of the following exception:

Traceback (most recent call last):
  File "C:\Users\Admin\Nilesh_Projects\CFA\cfa_ai_app\backend\venv\Lib\site-packages\requests\adapters.py", line 667, in send
    resp = conn.urlopen(
        method=request.method,
    ...<9 lines>...
        chunked=chunked,
    )
  File "C:\Users\Admin\Nilesh_Projects\CFA\cfa_ai_app\backend\venv\Lib\site-packages\urllib3\connectionpool.py", line 841, in urlopen
    retries = retries.increment(
        method, url, error=new_e, _pool=self, _stacktrace=sys.exc_info()[2]
    )
  File "C:\Users\Admin\Nilesh_Projects\CFA\cfa_ai_app\backend\venv\Lib\site-packages\urllib3\util\retry.py", line 474, in increment
    raise reraise(type(error), error, _stacktrace)
          ~~~~~~~^^^^^^^^^^^^^^^^^^^^^^^^^^^^^^^^^
  File "C:\Users\Admin\Nilesh_Projects\CFA\cfa_ai_app\backend\venv\Lib\site-packages\urllib3\util\util.py", line 39, in reraise
    raise value
  File "C:\Users\Admin\Nilesh_Projects\CFA\cfa_ai_app\backend\venv\Lib\site-packages\urllib3\connectionpool.py", line 787, in urlopen
    response = self._make_request(
        conn,
    ...<10 lines>...
        **response_kw,
    )
  File "C:\Users\Admin\Nilesh_Projects\CFA\cfa_ai_app\backend\venv\Lib\site-packages\urllib3\connectionpool.py", line 536, in _make_request
    self._raise_timeout(err=e, url=url, timeout_value=read_timeout)
    ~~~~~~~~~~~~~~~~~~~^^^^^^^^^^^^^^^^^^^^^^^^^^^^^^^^^^^^^^^^^^^^
  File "C:\Users\Admin\Nilesh_Projects\CFA\cfa_ai_app\backend\venv\Lib\site-packages\urllib3\connectionpool.py", line 367, in _raise_timeout
    raise ReadTimeoutError(
        self, url, f"Read timed out. (read timeout={timeout_value})"
    ) from err
urllib3.exceptions.ReadTimeoutError: HTTPConnectionPool(host='localhost', port=9000): Read timed out. (read timeout=150)

During handling of the above exception, another exception occurred:

Traceback (most recent call last):
  File "C:\Users\Admin\Nilesh_Projects\CFA\cfa_ai_app\Desktop_tally_sync-agent\tally_connector.py", line 52, in test_tally_connection
    response = requests.post(TALLY_URL, data=test_request, timeout=150)  # 2 minutes
  File "C:\Users\Admin\Nilesh_Projects\CFA\cfa_ai_app\backend\venv\Lib\site-packages\requests\api.py", line 115, in post
    return request("post", url, data=data, json=json, **kwargs)
  File "C:\Users\Admin\Nilesh_Projects\CFA\cfa_ai_app\backend\venv\Lib\site-packages\requests\api.py", line 59, in request
    return session.request(method=method, url=url, **kwargs)
           ~~~~~~~~~~~~~~~^^^^^^^^^^^^^^^^^^^^^^^^^^^^^^^^^^
  File "C:\Users\Admin\Nilesh_Projects\CFA\cfa_ai_app\backend\venv\Lib\site-packages\requests\sessions.py", line 589, in request
    resp = self.send(prep, **send_kwargs)
  File "C:\Users\Admin\Nilesh_Projects\CFA\cfa_ai_app\backend\venv\Lib\site-packages\requests\sessions.py", line 703, in send
    r = adapter.send(request, **kwargs)
  File "C:\Users\Admin\Nilesh_Projects\CFA\cfa_ai_app\backend\venv\Lib\site-packages\requests\adapters.py", line 713, in send
    raise ReadTimeout(e, request=request)
requests.exceptions.ReadTimeout: HTTPConnectionPool(host='localhost', port=9000): Read timed out. (read timeout=150)

[2025-07-06 20:43:46] Tally not connected. Sync aborted.
[2025-07-06 21:06:31] Sync Data button clicked.
[2025-07-06 21:06:31] Sending test connection POST to http://localhost:9000
[2025-07-06 21:06:42] Loaded TALLY_URL: http://localhost:9000
[2025-07-06 21:06:44] Sync Data button clicked.
[2025-07-06 21:06:44] Sending test connection POST to http://localhost:9000
[2025-07-06 21:07:14] Test connection response: status=200, text=<ENVELOPE>

 <HEADER>

  <TALLYREQUEST>Import Data</TALLYREQUEST>

 </HEADER>

 <BODY>

  <IMPORTDATA>

   <REQUESTDESC>

    <REPORTNAME>All Masters</REPORTNAME>

    <STATICVARIABLES>

     <SVCURRE
[2025-07-06 21:07:14] Tally connected. Fetching data...
[2025-07-06 21:07:14] Sending data request to http://localhost:9000 with XML: 
    <ENVELOPE>
        <HEADER>
            <TALLYREQUEST>Export Data</TALLYREQUEST>
        </HEAD
[2025-07-06 21:07:22] Data request response: status=200, text=<ENVELOPE>

 <VOUCHERDATE></VOUCHERDATE>

 <VOUCHERTYPE>Sales</VOUCHERTYPE>

 <VOUCHERNUMBER>24-25/01</VOUCHERNUMBER>

 <PARTYNAME>BHS-SONTHOFEN INDIA PRIVATE LIMITED</PARTYNAME>

 <VOUCHERAMOUNT>10,6
[2025-07-06 21:07:22] ❌ Failed to parse Tally XML: not well-formed (invalid token): line 52, column 32
Snippet: <ENVELOPE>

 <VOUCHERDATE></VOUCHERDATE>

 <VOUCHERTYPE>Sales</VOUCHERTYPE>

 <VOUCHERNUMBER>24-25/01</VOUCHERNUMBER>

 <PARTYNAME>BHS-SONTHOFEN INDIA PRIVATE LIMITED</PARTYNAME>

 <VOUCHERAMOUNT>10,67,900.00</VOUCHERAMOUNT>

 <VOUCHERDATE></VOUCHERDATE>

 <VOUCHERTYPE>Sales</VOUCHERTYPE>

 <VOUCHERNUMBER>24-25/02</VOUCHERNUMBER>

 <PARTYNAME>BHS-SONTHOFEN INDIA PRIVATE LIMITED</PARTYNAME>

 <VOUCHERAMOUNT>15,659.00</VOUCHERAMOUNT>

 <VOUCHERDATE></VOUCHERDATE>

 <VOUCHERTYPE>Sales</VOUCHERTYPE>
[2025-07-06 21:08:02] No data fetched from Tally.
[2025-07-06 21:13:53] Loaded TALLY_URL: http://localhost:9000
[2025-07-06 21:13:55] Sync Data button clicked.
[2025-07-06 21:13:55] Sending test connection POST to http://localhost:9000
[2025-07-06 21:16:44] ❌ Connection failed: HTTPConnectionPool(host='localhost', port=9000): Read timed out. (read timeout=150)
Traceback (most recent call last):
  File "C:\Users\Admin\Nilesh_Projects\CFA\cfa_ai_app\backend\venv\Lib\site-packages\urllib3\connectionpool.py", line 534, in _make_request
    response = conn.getresponse()
  File "C:\Users\Admin\Nilesh_Projects\CFA\cfa_ai_app\backend\venv\Lib\site-packages\urllib3\connection.py", line 565, in getresponse
    httplib_response = super().getresponse()
  File "C:\Users\Admin\AppData\Local\Programs\Python\Python313\Lib\http\client.py", line 1430, in getresponse
    response.begin()
    ~~~~~~~~~~~~~~^^
  File "C:\Users\Admin\AppData\Local\Programs\Python\Python313\Lib\http\client.py", line 331, in begin
    version, status, reason = self._read_status()
                              ~~~~~~~~~~~~~~~~~^^
  File "C:\Users\Admin\AppData\Local\Programs\Python\Python313\Lib\http\client.py", line 292, in _read_status
    line = str(self.fp.readline(_MAXLINE + 1), "iso-8859-1")
               ~~~~~~~~~~~~~~~~^^^^^^^^^^^^^^
  File "C:\Users\Admin\AppData\Local\Programs\Python\Python313\Lib\socket.py", line 719, in readinto
    return self._sock.recv_into(b)
           ~~~~~~~~~~~~~~~~~~~~^^^
TimeoutError: timed out

The above exception was the direct cause of the following exception:

Traceback (most recent call last):
  File "C:\Users\Admin\Nilesh_Projects\CFA\cfa_ai_app\backend\venv\Lib\site-packages\requests\adapters.py", line 667, in send
    resp = conn.urlopen(
        method=request.method,
    ...<9 lines>...
        chunked=chunked,
    )
  File "C:\Users\Admin\Nilesh_Projects\CFA\cfa_ai_app\backend\venv\Lib\site-packages\urllib3\connectionpool.py", line 841, in urlopen
    retries = retries.increment(
        method, url, error=new_e, _pool=self, _stacktrace=sys.exc_info()[2]
    )
  File "C:\Users\Admin\Nilesh_Projects\CFA\cfa_ai_app\backend\venv\Lib\site-packages\urllib3\util\retry.py", line 474, in increment
    raise reraise(type(error), error, _stacktrace)
          ~~~~~~~^^^^^^^^^^^^^^^^^^^^^^^^^^^^^^^^^
  File "C:\Users\Admin\Nilesh_Projects\CFA\cfa_ai_app\backend\venv\Lib\site-packages\urllib3\util\util.py", line 39, in reraise
    raise value
  File "C:\Users\Admin\Nilesh_Projects\CFA\cfa_ai_app\backend\venv\Lib\site-packages\urllib3\connectionpool.py", line 787, in urlopen
    response = self._make_request(
        conn,
    ...<10 lines>...
        **response_kw,
    )
  File "C:\Users\Admin\Nilesh_Projects\CFA\cfa_ai_app\backend\venv\Lib\site-packages\urllib3\connectionpool.py", line 536, in _make_request
    self._raise_timeout(err=e, url=url, timeout_value=read_timeout)
    ~~~~~~~~~~~~~~~~~~~^^^^^^^^^^^^^^^^^^^^^^^^^^^^^^^^^^^^^^^^^^^^
  File "C:\Users\Admin\Nilesh_Projects\CFA\cfa_ai_app\backend\venv\Lib\site-packages\urllib3\connectionpool.py", line 367, in _raise_timeout
    raise ReadTimeoutError(
        self, url, f"Read timed out. (read timeout={timeout_value})"
    ) from err
urllib3.exceptions.ReadTimeoutError: HTTPConnectionPool(host='localhost', port=9000): Read timed out. (read timeout=150)

During handling of the above exception, another exception occurred:

Traceback (most recent call last):
  File "C:\Users\Admin\Nilesh_Projects\CFA\cfa_ai_app\Desktop_tally_sync-agent\tally_connector.py", line 52, in test_tally_connection
    response = requests.post(TALLY_URL, data=test_request, timeout=150)  # 2 minutes
  File "C:\Users\Admin\Nilesh_Projects\CFA\cfa_ai_app\backend\venv\Lib\site-packages\requests\api.py", line 115, in post
    return request("post", url, data=data, json=json, **kwargs)
  File "C:\Users\Admin\Nilesh_Projects\CFA\cfa_ai_app\backend\venv\Lib\site-packages\requests\api.py", line 59, in request
    return session.request(method=method, url=url, **kwargs)
           ~~~~~~~~~~~~~~~^^^^^^^^^^^^^^^^^^^^^^^^^^^^^^^^^^
  File "C:\Users\Admin\Nilesh_Projects\CFA\cfa_ai_app\backend\venv\Lib\site-packages\requests\sessions.py", line 589, in request
    resp = self.send(prep, **send_kwargs)
  File "C:\Users\Admin\Nilesh_Projects\CFA\cfa_ai_app\backend\venv\Lib\site-packages\requests\sessions.py", line 703, in send
    r = adapter.send(request, **kwargs)
  File "C:\Users\Admin\Nilesh_Projects\CFA\cfa_ai_app\backend\venv\Lib\site-packages\requests\adapters.py", line 713, in send
    raise ReadTimeout(e, request=request)
requests.exceptions.ReadTimeout: HTTPConnectionPool(host='localhost', port=9000): Read timed out. (read timeout=150)

[2025-07-06 21:16:47] Tally not connected. Sync aborted.
[2025-07-06 21:36:26] Loaded TALLY_URL: http://localhost:9000
[2025-07-06 21:36:28] Sync Data button clicked.
[2025-07-06 21:36:28] Sending test connection POST to http://localhost:9000
[2025-07-06 21:36:56] Test connection response: status=200, text=<ENVELOPE>

 <HEADER>

  <TALLYREQUEST>Import Data</TALLYREQUEST>

 </HEADER>

 <BODY>

  <IMPORTDATA>

   <REQUESTDESC>

    <REPORTNAME>All Masters</REPORTNAME>

    <STATICVARIABLES>

     <SVCURRE
[2025-07-06 21:36:57] Tally connected. Fetching data...
[2025-07-06 21:36:57] Sending data request to http://localhost:9000 with XML: 
    <ENVELOPE>
        <HEADER>
            <TALLYREQUEST>Export Data</TALLYREQUEST>
        </HEAD
[2025-07-06 21:39:00] ❌ Timeout while connecting to Tally.
[2025-07-06 21:40:12] No data fetched from Tally.
[2025-07-06 21:44:37] Loaded TALLY_URL: http://localhost:9000
[2025-07-06 21:44:39] Sync Data button clicked.
[2025-07-06 21:44:39] Sending test connection POST to http://localhost:9000
[2025-07-06 21:45:08] Test connection response: status=200, text=<ENVELOPE>

 <HEADER>

  <TALLYREQUEST>Import Data</TALLYREQUEST>

 </HEADER>

 <BODY>

  <IMPORTDATA>

   <REQUESTDESC>

    <REPORTNAME>All Masters</REPORTNAME>

    <STATICVARIABLES>

     <SVCURRE
[2025-07-06 21:45:08] Tally connected. Fetching data...
[2025-07-06 21:45:08] Sending data request to http://localhost:9000 with XML: 
    <ENVELOPE>
        <HEADER>
            <TALLYREQUEST>Export Data</TALLYREQUEST>
        </HEAD
[2025-07-06 21:46:11] ❌ Error fetching data from Tally: ('Connection aborted.', ConnectionResetError(10054, 'An existing connection was forcibly closed by the remote host', None, 10054, None))
[2025-07-06 21:46:13] No data fetched from Tally.
[2025-07-06 21:49:01] Loaded TALLY_URL: http://localhost:9000
[2025-07-06 21:49:05] Sync Data button clicked.
[2025-07-06 21:49:05] Sending test connection POST to http://localhost:9000
[2025-07-06 21:49:34] Test connection response: status=200, text=<ENVELOPE>

 <HEADER>

  <TALLYREQUEST>Import Data</TALLYREQUEST>

 </HEADER>

 <BODY>

  <IMPORTDATA>

   <REQUESTDESC>

    <REPORTNAME>All Masters</REPORTNAME>

    <STATICVARIABLES>

     <SVCURRE
[2025-07-06 21:49:34] Tally connected. Fetching data...
[2025-07-06 21:49:34] Sending data request to http://localhost:9000 with XML: 
    <ENVELOPE>
        <HEADER>
            <TALLYREQUEST>Export Data</TALLYREQUEST>
        </HEAD
[2025-07-06 21:51:48] ❌ Timeout while connecting to Tally.
[2025-07-06 21:51:56] No data fetched from Tally.
[2025-07-06 22:02:17] Sync Data button clicked.
[2025-07-06 22:02:17] Sending test connection POST to http://localhost:9000
[2025-07-06 22:02:28] Loaded TALLY_URL: http://localhost:9000
[2025-07-06 22:02:31] Sync Data button clicked.
[2025-07-06 22:02:31] Sending test connection POST to http://localhost:9000
[2025-07-06 22:02:58] Test connection response: status=200, text=<ENVELOPE>

 <HEADER>

  <TALLYREQUEST>Import Data</TALLYREQUEST>

 </HEADER>

 <BODY>

  <IMPORTDATA>

   <REQUESTDESC>

    <REPORTNAME>All Masters</REPORTNAME>

    <STATICVARIABLES>

     <SVCURRE
[2025-07-06 22:02:59] Tally connected. Fetching data...
[2025-07-06 22:02:59] Sending data request to http://localhost:9000 with XML: 
    <ENVELOPE>
        <HEADER>
            <TALLYREQUEST>Export Data</TALLYREQUEST>
        </HEAD
[2025-07-06 22:05:02] ❌ Timeout while connecting to Tally.
[2025-07-06 22:11:51] No data fetched from Tally.
[2025-07-06 22:12:09] Loaded TALLY_URL: http://localhost:9000
[2025-07-06 22:12:12] Sync Data button clicked.
[2025-07-06 22:12:12] Sending test connection POST to http://localhost:9000
[2025-07-06 22:12:41] Test connection response: status=200, text=<ENVELOPE>

 <HEADER>

  <TALLYREQUEST>Import Data</TALLYREQUEST>

 </HEADER>

 <BODY>

  <IMPORTDATA>

   <REQUESTDESC>

    <REPORTNAME>All Masters</REPORTNAME>

    <STATICVARIABLES>

     <SVCURRE
[2025-07-06 22:12:41] Tally connected. Fetching data...
[2025-07-06 22:12:41] Sending data request to http://localhost:9000 with XML: 
    <ENVELOPE>
        <HEADER>
            <TALLYREQUEST>Export Data</TALLYREQUEST>
        </HEAD
[2025-07-06 22:15:24] ❌ Timeout while connecting to Tally.
[2025-07-06 22:15:37] No data fetched from Tally.
[2025-07-06 22:26:00] Loaded TALLY_URL: http://localhost:9000
[2025-07-06 22:26:05] Sync Data button clicked.
[2025-07-06 22:26:05] Sending test connection POST to http://localhost:9000
[2025-07-06 22:26:30] Test connection response: status=200, text=<ENVELOPE>

 <HEADER>

  <TALLYREQUEST>Import Data</TALLYREQUEST>

 </HEADER>

 <BODY>

  <IMPORTDATA>

   <REQUESTDESC>

    <REPORTNAME>All Masters</REPORTNAME>

    <STATICVARIABLES>

     <SVCURRE
[2025-07-06 22:26:30] Tally connected. Fetching data...
[2025-07-06 22:26:30] Sending data request to http://localhost:9000 with XML: 
    <ENVELOPE>
        <HEADER>
            <TALLYREQUEST>Export Data</TALLYREQUEST>
        </HEAD
[2025-07-06 22:28:32] ❌ Timeout while connecting to Tally.
[2025-07-06 22:32:19] No data fetched from Tally.
[2025-07-06 22:39:10] Loaded TALLY_URL: http://localhost:9000
[2025-07-06 22:39:15] Sync Data button clicked.
[2025-07-06 22:39:15] Sending test connection POST to http://localhost:9000
[2025-07-06 22:39:41] Test connection response: status=200, text=<ENVELOPE>

 <HEADER>

  <TALLYREQUEST>Import Data</TALLYREQUEST>

 </HEADER>

 <BODY>

  <IMPORTDATA>

   <REQUESTDESC>

    <REPORTNAME>All Masters</REPORTNAME>

    <STATICVARIABLES>

     <SVCURRE
[2025-07-06 22:39:41] Tally connected. Fetching data...
[2025-07-06 22:39:41] Sending data request to http://localhost:9000 with XML: 
    <ENVELOPE>
        <HEADER>
            <TALLYREQUEST>Export Data</TALLYREQUEST>
        </HEAD
[2025-07-06 22:41:53] ❌ Timeout while connecting to Tally.
[2025-07-06 22:42:37] No data fetched from Tally.
[2025-07-06 22:43:35] Loaded TALLY_URL: http://localhost:9000
[2025-07-06 22:43:37] Sync Data button clicked.
[2025-07-06 22:43:37] Sending test connection POST to http://localhost:9000
[2025-07-06 22:43:59] Test connection response: status=200, text=<ENVELOPE>

 <HEADER>

  <TALLYREQUEST>Import Data</TALLYREQUEST>

 </HEADER>

 <BODY>

  <IMPORTDATA>

   <REQUESTDESC>

    <REPORTNAME>All Masters</REPORTNAME>

    <STATICVARIABLES>

     <SVCURRE
[2025-07-06 22:43:59] Tally connected. Fetching data...
[2025-07-06 22:43:59] Sending data request to http://localhost:9000 with XML: 
    <ENVELOPE>
        <HEADER>
            <TALLYREQUEST>Export Data</TALLYREQUEST>
        </HEAD
[2025-07-06 22:47:35] ❌ Timeout while connecting to Tally.
[2025-07-06 22:48:35] No data fetched from Tally.
[2025-07-06 22:49:20] Loaded TALLY_URL: http://localhost:9000
[2025-07-06 22:49:23] Sync Data button clicked.
[2025-07-06 22:49:23] Sending test connection POST to http://localhost:9000
[2025-07-06 22:49:45] Test connection response: status=200, text=<ENVELOPE>

 <HEADER>

  <TALLYREQUEST>Import Data</TALLYREQUEST>

 </HEADER>

 <BODY>

  <IMPORTDATA>

   <REQUESTDESC>

    <REPORTNAME>All Masters</REPORTNAME>

    <STATICVARIABLES>

     <SVCURRE
[2025-07-06 22:49:45] Tally connected. Fetching data...
[2025-07-06 22:49:45] Sending data request to http://localhost:9000 with XML: 
    <ENVELOPE>
        <HEADER>
            <TALLYREQUEST>Export Data</TALLYREQUEST>
        </HEAD
[2025-07-06 22:50:49] ❌ Error fetching data from Tally: ('Connection aborted.', ConnectionResetError(10054, 'An existing connection was forcibly closed by the remote host', None, 10054, None))
[2025-07-06 22:50:56] No data fetched from Tally.
[2025-07-06 22:55:12] Sync Data button clicked.
[2025-07-06 22:55:12] Sending test connection POST to http://localhost:9000
[2025-07-06 22:55:58] Test connection response: status=200, text=<ENVELOPE>

 <HEADER>

  <TALLYREQUEST>Import Data</TALLYREQUEST>

 </HEADER>

 <BODY>

  <IMPORTDATA>

   <REQUESTDESC>

    <REPORTNAME>All Masters</REPORTNAME>

    <STATICVARIABLES>

     <SVCURRE
[2025-07-06 22:55:58] Tally connected. Fetching data...
[2025-07-06 22:55:58] Sending data request to http://localhost:9000 with XML: 
    <ENVELOPE>
        <HEADER>
            <TALLYREQUEST>Export Data</TALLYREQUEST>
        </HEAD
[2025-07-06 22:56:32] ❌ Error fetching data from Tally: ('Connection aborted.', ConnectionResetError(10054, 'An existing connection was forcibly closed by the remote host', None, 10054, None))
[2025-07-06 22:56:35] No data fetched from Tally.
[2025-07-06 23:09:44] Loaded TALLY_URL: http://localhost:9000
[2025-07-06 23:09:47] Sync Data button clicked.
[2025-07-06 23:09:47] Sending test connection POST to http://localhost:9000
[2025-07-06 23:10:11] Test connection response: status=200, text=<ENVELOPE>

 <HEADER>

  <TALLYREQUEST>Import Data</TALLYREQUEST>

 </HEADER>

 <BODY>

  <IMPORTDATA>

   <REQUESTDESC>

    <REPORTNAME>All Masters</REPORTNAME>

    <STATICVARIABLES>

     <SVCURRE
[2025-07-06 23:10:11] Tally connected. Fetching data...
[2025-07-06 23:10:11] Sending data request to http://localhost:9000 with XML: 
    <ENVELOPE>
        <HEADER>
            <TALLYREQUEST>Export Data</TALLYREQUEST>
        </HEAD
[2025-07-06 23:12:14] ❌ Timeout while connecting to Tally.
[2025-07-06 23:20:24] No data fetched from Tally.
[2025-07-06 23:20:29] Sync Data button clicked.
[2025-07-06 23:20:29] Sending test connection POST to http://localhost:9000
[2025-07-06 23:20:55] Test connection response: status=200, text=<ENVELOPE>

 <HEADER>

  <TALLYREQUEST>Import Data</TALLYREQUEST>

 </HEADER>

 <BODY>

  <IMPORTDATA>

   <REQUESTDESC>

    <REPORTNAME>All Masters</REPORTNAME>

    <STATICVARIABLES>

     <SVCURRE
[2025-07-06 23:20:55] Tally connected. Fetching data...
[2025-07-06 23:20:55] Sending data request to http://localhost:9000 with XML: 
    <ENVELOPE>
        <HEADER>
            <TALLYREQUEST>Export Data</TALLYREQUEST>
        </HEAD
[2025-07-06 23:21:07] Data request response: status=200, text=<ENVELOPE>

 <VOUCHERDATE></VOUCHERDATE>

 <VOUCHERTYPE>Sales</VOUCHERTYPE>

 <VOUCHERNUMBER>24-25/01</VOUCHERNUMBER>

 <PARTYNAME>BHS-SONTHOFEN INDIA PRIVATE LIMITED</PARTYNAME>

 <VOUCHERAMOUNT>1067
[2025-07-06 23:21:07] ❌ Failed to parse Tally XML: not well-formed (invalid token): line 91, column 32
Snippet: <ENVELOPE>

 <VOUCHERDATE></VOUCHERDATE>

 <VOUCHERTYPE>Sales</VOUCHERTYPE>

 <VOUCHERNUMBER>24-25/01</VOUCHERNUMBER>

 <PARTYNAME>BHS-SONTHOFEN INDIA PRIVATE LIMITED</PARTYNAME>

 <VOUCHERAMOUNT>1067900</VOUCHERAMOUNT>

 <NARRATIONFIELDEXPORT></NARRATIONFIELDEXPORT>

 <VOUCHERDATE></VOUCHERDATE>

 <VOUCHERTYPE>Sales</VOUCHERTYPE>

 <VOUCHERNUMBER>24-25/02</VOUCHERNUMBER>

 <PARTYNAME>BHS-SONTHOFEN INDIA PRIVATE LIMITED</PARTYNAME>

 <VOUCHERAMOUNT>15659</VOUCHERAMOUNT>

 <NARRATIONFIELDEXPORT><
[2025-07-06 23:23:06] No data fetched from Tally.
[2025-07-06 23:23:09] Sync Data button clicked.
[2025-07-06 23:23:09] Sending test connection POST to http://localhost:9000
[2025-07-06 23:23:26] Loaded TALLY_URL: http://localhost:9000
[2025-07-06 23:23:31] Sync Data button clicked.
[2025-07-06 23:23:31] Sending test connection POST to http://localhost:9000
[2025-07-06 23:26:07] ❌ Connection failed: HTTPConnectionPool(host='localhost', port=9000): Read timed out. (read timeout=150)
Traceback (most recent call last):
  File "C:\Users\Admin\Nilesh_Projects\CFA\cfa_ai_app\backend\venv\Lib\site-packages\urllib3\connectionpool.py", line 534, in _make_request
    response = conn.getresponse()
  File "C:\Users\Admin\Nilesh_Projects\CFA\cfa_ai_app\backend\venv\Lib\site-packages\urllib3\connection.py", line 565, in getresponse
    httplib_response = super().getresponse()
  File "C:\Users\Admin\AppData\Local\Programs\Python\Python313\Lib\http\client.py", line 1430, in getresponse
    response.begin()
    ~~~~~~~~~~~~~~^^
  File "C:\Users\Admin\AppData\Local\Programs\Python\Python313\Lib\http\client.py", line 331, in begin
    version, status, reason = self._read_status()
                              ~~~~~~~~~~~~~~~~~^^
  File "C:\Users\Admin\AppData\Local\Programs\Python\Python313\Lib\http\client.py", line 292, in _read_status
    line = str(self.fp.readline(_MAXLINE + 1), "iso-8859-1")
               ~~~~~~~~~~~~~~~~^^^^^^^^^^^^^^
  File "C:\Users\Admin\AppData\Local\Programs\Python\Python313\Lib\socket.py", line 719, in readinto
    return self._sock.recv_into(b)
           ~~~~~~~~~~~~~~~~~~~~^^^
TimeoutError: timed out

The above exception was the direct cause of the following exception:

Traceback (most recent call last):
  File "C:\Users\Admin\Nilesh_Projects\CFA\cfa_ai_app\backend\venv\Lib\site-packages\requests\adapters.py", line 667, in send
    resp = conn.urlopen(
        method=request.method,
    ...<9 lines>...
        chunked=chunked,
    )
  File "C:\Users\Admin\Nilesh_Projects\CFA\cfa_ai_app\backend\venv\Lib\site-packages\urllib3\connectionpool.py", line 841, in urlopen
    retries = retries.increment(
        method, url, error=new_e, _pool=self, _stacktrace=sys.exc_info()[2]
    )
  File "C:\Users\Admin\Nilesh_Projects\CFA\cfa_ai_app\backend\venv\Lib\site-packages\urllib3\util\retry.py", line 474, in increment
    raise reraise(type(error), error, _stacktrace)
          ~~~~~~~^^^^^^^^^^^^^^^^^^^^^^^^^^^^^^^^^
  File "C:\Users\Admin\Nilesh_Projects\CFA\cfa_ai_app\backend\venv\Lib\site-packages\urllib3\util\util.py", line 39, in reraise
    raise value
  File "C:\Users\Admin\Nilesh_Projects\CFA\cfa_ai_app\backend\venv\Lib\site-packages\urllib3\connectionpool.py", line 787, in urlopen
    response = self._make_request(
        conn,
    ...<10 lines>...
        **response_kw,
    )
  File "C:\Users\Admin\Nilesh_Projects\CFA\cfa_ai_app\backend\venv\Lib\site-packages\urllib3\connectionpool.py", line 536, in _make_request
    self._raise_timeout(err=e, url=url, timeout_value=read_timeout)
    ~~~~~~~~~~~~~~~~~~~^^^^^^^^^^^^^^^^^^^^^^^^^^^^^^^^^^^^^^^^^^^^
  File "C:\Users\Admin\Nilesh_Projects\CFA\cfa_ai_app\backend\venv\Lib\site-packages\urllib3\connectionpool.py", line 367, in _raise_timeout
    raise ReadTimeoutError(
        self, url, f"Read timed out. (read timeout={timeout_value})"
    ) from err
urllib3.exceptions.ReadTimeoutError: HTTPConnectionPool(host='localhost', port=9000): Read timed out. (read timeout=150)

During handling of the above exception, another exception occurred:

Traceback (most recent call last):
  File "C:\Users\Admin\Nilesh_Projects\CFA\cfa_ai_app\Desktop_tally_sync-agent\tally_connector.py", line 52, in test_tally_connection
    response = requests.post(TALLY_URL, data=test_request, timeout=150)  # 2 minutes
  File "C:\Users\Admin\Nilesh_Projects\CFA\cfa_ai_app\backend\venv\Lib\site-packages\requests\api.py", line 115, in post
    return request("post", url, data=data, json=json, **kwargs)
  File "C:\Users\Admin\Nilesh_Projects\CFA\cfa_ai_app\backend\venv\Lib\site-packages\requests\api.py", line 59, in request
    return session.request(method=method, url=url, **kwargs)
           ~~~~~~~~~~~~~~~^^^^^^^^^^^^^^^^^^^^^^^^^^^^^^^^^^
  File "C:\Users\Admin\Nilesh_Projects\CFA\cfa_ai_app\backend\venv\Lib\site-packages\requests\sessions.py", line 589, in request
    resp = self.send(prep, **send_kwargs)
  File "C:\Users\Admin\Nilesh_Projects\CFA\cfa_ai_app\backend\venv\Lib\site-packages\requests\sessions.py", line 703, in send
    r = adapter.send(request, **kwargs)
  File "C:\Users\Admin\Nilesh_Projects\CFA\cfa_ai_app\backend\venv\Lib\site-packages\requests\adapters.py", line 713, in send
    raise ReadTimeout(e, request=request)
requests.exceptions.ReadTimeout: HTTPConnectionPool(host='localhost', port=9000): Read timed out. (read timeout=150)

[2025-07-06 23:34:04] Tally not connected. Sync aborted.
[2025-07-06 23:41:31] Sync Data button clicked.
[2025-07-06 23:41:31] Sending test connection POST to http://localhost:9000
[2025-07-06 23:41:52] Test connection response: status=200, text=<ENVELOPE>

 <HEADER>

  <TALLYREQUEST>Import Data</TALLYREQUEST>

 </HEADER>

 <BODY>

  <IMPORTDATA>

   <REQUESTDESC>

    <REPORTNAME>All Masters</REPORTNAME>

    <STATICVARIABLES>

     <SVCURRE
[2025-07-06 23:41:52] Tally connected. Fetching data...
[2025-07-06 23:41:52] Sending data request to http://localhost:9000 with XML: 
    <ENVELOPE>
        <HEADER>
            <TALLYREQUEST>Export Data</TALLYREQUEST>
        </HEAD
[2025-07-06 23:42:28] ❌ Error fetching data from Tally: ('Connection aborted.', ConnectionResetError(10054, 'An existing connection was forcibly closed by the remote host', None, 10054, None))
[2025-07-06 23:44:31] No data fetched from Tally.
[2025-07-06 23:44:33] Sync Data button clicked.
[2025-07-06 23:44:33] Sending test connection POST to http://localhost:9000
[2025-07-06 23:44:55] Test connection response: status=200, text=<ENVELOPE>

 <HEADER>

  <TALLYREQUEST>Import Data</TALLYREQUEST>

 </HEADER>

 <BODY>

  <IMPORTDATA>

   <REQUESTDESC>

    <REPORTNAME>All Masters</REPORTNAME>

    <STATICVARIABLES>

     <SVCURRE
[2025-07-06 23:44:55] Tally connected. Fetching data...
[2025-07-06 23:44:55] Sending data request to http://localhost:9000 with XML: 
    <ENVELOPE>
        <HEADER>
            <TALLYREQUEST>Export Data</TALLYREQUEST>
        </HEAD
[2025-07-06 23:45:01] Data request response: status=200, text=<ENVELOPE>

 <VOUCHERDATE></VOUCHERDATE>

 <VOUCHERTYPE>Sales</VOUCHERTYPE>

 <VOUCHERNUMBER>24-25/01</VOUCHERNUMBER>

 <PARTYNAME>BHS-SONTHOFEN INDIA PRIVATE LIMITED</PARTYNAME>

 <VOUCHERAMOUNT>1067
[2025-07-06 23:45:01] ❌ Failed to parse Tally XML: not well-formed (invalid token): line 91, column 32
Snippet: <ENVELOPE>

 <VOUCHERDATE></VOUCHERDATE>

 <VOUCHERTYPE>Sales</VOUCHERTYPE>

 <VOUCHERNUMBER>24-25/01</VOUCHERNUMBER>

 <PARTYNAME>BHS-SONTHOFEN INDIA PRIVATE LIMITED</PARTYNAME>

 <VOUCHERAMOUNT>1067900</VOUCHERAMOUNT>

 <NARRATIONFIELDEXPORT></NARRATIONFIELDEXPORT>

 <VOUCHERDATE></VOUCHERDATE>

 <VOUCHERTYPE>Sales</VOUCHERTYPE>

 <VOUCHERNUMBER>24-25/02</VOUCHERNUMBER>

 <PARTYNAME>BHS-SONTHOFEN INDIA PRIVATE LIMITED</PARTYNAME>

 <VOUCHERAMOUNT>15659</VOUCHERAMOUNT>

 <NARRATIONFIELDEXPORT><
[2025-07-06 23:45:47] No data fetched from Tally.
[2025-07-06 23:48:43] Sync Data button clicked.
[2025-07-06 23:48:43] Sending test connection POST to http://localhost:9000
[2025-07-06 23:49:32] ❌ Connection failed: ('Connection aborted.', ConnectionResetError(10054, 'An existing connection was forcibly closed by the remote host', None, 10054, None))
Traceback (most recent call last):
  File "C:\Users\Admin\Nilesh_Projects\CFA\cfa_ai_app\backend\venv\Lib\site-packages\urllib3\connectionpool.py", line 787, in urlopen
    response = self._make_request(
        conn,
    ...<10 lines>...
        **response_kw,
    )
  File "C:\Users\Admin\Nilesh_Projects\CFA\cfa_ai_app\backend\venv\Lib\site-packages\urllib3\connectionpool.py", line 534, in _make_request
    response = conn.getresponse()
  File "C:\Users\Admin\Nilesh_Projects\CFA\cfa_ai_app\backend\venv\Lib\site-packages\urllib3\connection.py", line 565, in getresponse
    httplib_response = super().getresponse()
  File "C:\Users\Admin\AppData\Local\Programs\Python\Python313\Lib\http\client.py", line 1430, in getresponse
    response.begin()
    ~~~~~~~~~~~~~~^^
  File "C:\Users\Admin\AppData\Local\Programs\Python\Python313\Lib\http\client.py", line 331, in begin
    version, status, reason = self._read_status()
                              ~~~~~~~~~~~~~~~~~^^
  File "C:\Users\Admin\AppData\Local\Programs\Python\Python313\Lib\http\client.py", line 292, in _read_status
    line = str(self.fp.readline(_MAXLINE + 1), "iso-8859-1")
               ~~~~~~~~~~~~~~~~^^^^^^^^^^^^^^
  File "C:\Users\Admin\AppData\Local\Programs\Python\Python313\Lib\socket.py", line 719, in readinto
    return self._sock.recv_into(b)
           ~~~~~~~~~~~~~~~~~~~~^^^
ConnectionResetError: [WinError 10054] An existing connection was forcibly closed by the remote host

During handling of the above exception, another exception occurred:

Traceback (most recent call last):
  File "C:\Users\Admin\Nilesh_Projects\CFA\cfa_ai_app\backend\venv\Lib\site-packages\requests\adapters.py", line 667, in send
    resp = conn.urlopen(
        method=request.method,
    ...<9 lines>...
        chunked=chunked,
    )
  File "C:\Users\Admin\Nilesh_Projects\CFA\cfa_ai_app\backend\venv\Lib\site-packages\urllib3\connectionpool.py", line 841, in urlopen
    retries = retries.increment(
        method, url, error=new_e, _pool=self, _stacktrace=sys.exc_info()[2]
    )
  File "C:\Users\Admin\Nilesh_Projects\CFA\cfa_ai_app\backend\venv\Lib\site-packages\urllib3\util\retry.py", line 474, in increment
    raise reraise(type(error), error, _stacktrace)
          ~~~~~~~^^^^^^^^^^^^^^^^^^^^^^^^^^^^^^^^^
  File "C:\Users\Admin\Nilesh_Projects\CFA\cfa_ai_app\backend\venv\Lib\site-packages\urllib3\util\util.py", line 38, in reraise
    raise value.with_traceback(tb)
  File "C:\Users\Admin\Nilesh_Projects\CFA\cfa_ai_app\backend\venv\Lib\site-packages\urllib3\connectionpool.py", line 787, in urlopen
    response = self._make_request(
        conn,
    ...<10 lines>...
        **response_kw,
    )
  File "C:\Users\Admin\Nilesh_Projects\CFA\cfa_ai_app\backend\venv\Lib\site-packages\urllib3\connectionpool.py", line 534, in _make_request
    response = conn.getresponse()
  File "C:\Users\Admin\Nilesh_Projects\CFA\cfa_ai_app\backend\venv\Lib\site-packages\urllib3\connection.py", line 565, in getresponse
    httplib_response = super().getresponse()
  File "C:\Users\Admin\AppData\Local\Programs\Python\Python313\Lib\http\client.py", line 1430, in getresponse
    response.begin()
    ~~~~~~~~~~~~~~^^
  File "C:\Users\Admin\AppData\Local\Programs\Python\Python313\Lib\http\client.py", line 331, in begin
    version, status, reason = self._read_status()
                              ~~~~~~~~~~~~~~~~~^^
  File "C:\Users\Admin\AppData\Local\Programs\Python\Python313\Lib\http\client.py", line 292, in _read_status
    line = str(self.fp.readline(_MAXLINE + 1), "iso-8859-1")
               ~~~~~~~~~~~~~~~~^^^^^^^^^^^^^^
  File "C:\Users\Admin\AppData\Local\Programs\Python\Python313\Lib\socket.py", line 719, in readinto
    return self._sock.recv_into(b)
           ~~~~~~~~~~~~~~~~~~~~^^^
urllib3.exceptions.ProtocolError: ('Connection aborted.', ConnectionResetError(10054, 'An existing connection was forcibly closed by the remote host', None, 10054, None))

During handling of the above exception, another exception occurred:

Traceback (most recent call last):
  File "C:\Users\Admin\Nilesh_Projects\CFA\cfa_ai_app\Desktop_tally_sync-agent\tally_connector.py", line 52, in test_tally_connection
    response = requests.post(TALLY_URL, data=test_request, timeout=150)  # 2 minutes
  File "C:\Users\Admin\Nilesh_Projects\CFA\cfa_ai_app\backend\venv\Lib\site-packages\requests\api.py", line 115, in post
    return request("post", url, data=data, json=json, **kwargs)
  File "C:\Users\Admin\Nilesh_Projects\CFA\cfa_ai_app\backend\venv\Lib\site-packages\requests\api.py", line 59, in request
    return session.request(method=method, url=url, **kwargs)
           ~~~~~~~~~~~~~~~^^^^^^^^^^^^^^^^^^^^^^^^^^^^^^^^^^
  File "C:\Users\Admin\Nilesh_Projects\CFA\cfa_ai_app\backend\venv\Lib\site-packages\requests\sessions.py", line 589, in request
    resp = self.send(prep, **send_kwargs)
  File "C:\Users\Admin\Nilesh_Projects\CFA\cfa_ai_app\backend\venv\Lib\site-packages\requests\sessions.py", line 703, in send
    r = adapter.send(request, **kwargs)
  File "C:\Users\Admin\Nilesh_Projects\CFA\cfa_ai_app\backend\venv\Lib\site-packages\requests\adapters.py", line 682, in send
    raise ConnectionError(err, request=request)
requests.exceptions.ConnectionError: ('Connection aborted.', ConnectionResetError(10054, 'An existing connection was forcibly closed by the remote host', None, 10054, None))

[2025-07-06 23:49:34] Tally not connected. Sync aborted.
[2025-07-06 23:55:02] Loaded TALLY_URL: http://localhost:9000
[2025-07-06 23:55:05] Sync Data button clicked.
[2025-07-06 23:55:05] Sending test connection POST to http://localhost:9000
[2025-07-06 23:55:28] Test connection response: status=200, text=<ENVELOPE>

 <HEADER>

  <TALLYREQUEST>Import Data</TALLYREQUEST>

 </HEADER>

 <BODY>

  <IMPORTDATA>

   <REQUESTDESC>

    <REPORTNAME>All Masters</REPORTNAME>

    <STATICVARIABLES>

     <SVCURRE
[2025-07-06 23:55:28] Tally connected. Fetching data...
[2025-07-06 23:55:28] Sending data request to http://localhost:9000 with XML: 
    <ENVELOPE>
        <HEADER>
            <TALLYREQUEST>Export Data</TALLYREQUEST>
        </HEAD
[2025-07-06 23:55:35] Data request response: status=200, text=<ENVELOPE>

 <VOUCHERDATE></VOUCHERDATE>

 <VOUCHERTYPE>Sales</VOUCHERTYPE>

 <VOUCHERNUMBER>24-25/01</VOUCHERNUMBER>

 <PARTYNAME>BHS-SONTHOFEN INDIA PRIVATE LIMITED</PARTYNAME>

 <VOUCHERAMOUNT>1067
[2025-07-06 23:55:35] ❌ Failed to parse Tally XML: not well-formed (invalid token): line 91, column 32
Snippet: <ENVELOPE>

 <VOUCHERDATE></VOUCHERDATE>

 <VOUCHERTYPE>Sales</VOUCHERTYPE>

 <VOUCHERNUMBER>24-25/01</VOUCHERNUMBER>

 <PARTYNAME>BHS-SONTHOFEN INDIA PRIVATE LIMITED</PARTYNAME>

 <VOUCHERAMOUNT>1067900</VOUCHERAMOUNT>

 <NARRATIONFIELDEXPORT></NARRATIONFIELDEXPORT>

 <VOUCHERDATE></VOUCHERDATE>

 <VOUCHERTYPE>Sales</VOUCHERTYPE>

 <VOUCHERNUMBER>24-25/02</VOUCHERNUMBER>

 <PARTYNAME>BHS-SONTHOFEN INDIA PRIVATE LIMITED</PARTYNAME>

 <VOUCHERAMOUNT>15659</VOUCHERAMOUNT>

 <NARRATIONFIELDEXPORT><
[2025-07-06 23:56:20] No data fetched from Tally.
[2025-07-07 00:03:18] Sync Data button clicked.
[2025-07-07 00:03:18] Sending test connection POST to http://localhost:9000
[2025-07-07 00:05:53] ❌ Connection failed: HTTPConnectionPool(host='localhost', port=9000): Read timed out. (read timeout=150)
Traceback (most recent call last):
  File "C:\Users\Admin\Nilesh_Projects\CFA\cfa_ai_app\backend\venv\Lib\site-packages\urllib3\connectionpool.py", line 534, in _make_request
    response = conn.getresponse()
  File "C:\Users\Admin\Nilesh_Projects\CFA\cfa_ai_app\backend\venv\Lib\site-packages\urllib3\connection.py", line 565, in getresponse
    httplib_response = super().getresponse()
  File "C:\Users\Admin\AppData\Local\Programs\Python\Python313\Lib\http\client.py", line 1430, in getresponse
    response.begin()
    ~~~~~~~~~~~~~~^^
  File "C:\Users\Admin\AppData\Local\Programs\Python\Python313\Lib\http\client.py", line 331, in begin
    version, status, reason = self._read_status()
                              ~~~~~~~~~~~~~~~~~^^
  File "C:\Users\Admin\AppData\Local\Programs\Python\Python313\Lib\http\client.py", line 292, in _read_status
    line = str(self.fp.readline(_MAXLINE + 1), "iso-8859-1")
               ~~~~~~~~~~~~~~~~^^^^^^^^^^^^^^
  File "C:\Users\Admin\AppData\Local\Programs\Python\Python313\Lib\socket.py", line 719, in readinto
    return self._sock.recv_into(b)
           ~~~~~~~~~~~~~~~~~~~~^^^
TimeoutError: timed out

The above exception was the direct cause of the following exception:

Traceback (most recent call last):
  File "C:\Users\Admin\Nilesh_Projects\CFA\cfa_ai_app\backend\venv\Lib\site-packages\requests\adapters.py", line 667, in send
    resp = conn.urlopen(
        method=request.method,
    ...<9 lines>...
        chunked=chunked,
    )
  File "C:\Users\Admin\Nilesh_Projects\CFA\cfa_ai_app\backend\venv\Lib\site-packages\urllib3\connectionpool.py", line 841, in urlopen
    retries = retries.increment(
        method, url, error=new_e, _pool=self, _stacktrace=sys.exc_info()[2]
    )
  File "C:\Users\Admin\Nilesh_Projects\CFA\cfa_ai_app\backend\venv\Lib\site-packages\urllib3\util\retry.py", line 474, in increment
    raise reraise(type(error), error, _stacktrace)
          ~~~~~~~^^^^^^^^^^^^^^^^^^^^^^^^^^^^^^^^^
  File "C:\Users\Admin\Nilesh_Projects\CFA\cfa_ai_app\backend\venv\Lib\site-packages\urllib3\util\util.py", line 39, in reraise
    raise value
  File "C:\Users\Admin\Nilesh_Projects\CFA\cfa_ai_app\backend\venv\Lib\site-packages\urllib3\connectionpool.py", line 787, in urlopen
    response = self._make_request(
        conn,
    ...<10 lines>...
        **response_kw,
    )
  File "C:\Users\Admin\Nilesh_Projects\CFA\cfa_ai_app\backend\venv\Lib\site-packages\urllib3\connectionpool.py", line 536, in _make_request
    self._raise_timeout(err=e, url=url, timeout_value=read_timeout)
    ~~~~~~~~~~~~~~~~~~~^^^^^^^^^^^^^^^^^^^^^^^^^^^^^^^^^^^^^^^^^^^^
  File "C:\Users\Admin\Nilesh_Projects\CFA\cfa_ai_app\backend\venv\Lib\site-packages\urllib3\connectionpool.py", line 367, in _raise_timeout
    raise ReadTimeoutError(
        self, url, f"Read timed out. (read timeout={timeout_value})"
    ) from err
urllib3.exceptions.ReadTimeoutError: HTTPConnectionPool(host='localhost', port=9000): Read timed out. (read timeout=150)

During handling of the above exception, another exception occurred:

Traceback (most recent call last):
  File "C:\Users\Admin\Nilesh_Projects\CFA\cfa_ai_app\Desktop_tally_sync-agent\tally_connector.py", line 52, in test_tally_connection
    response = requests.post(TALLY_URL, data=test_request, timeout=150)  # 2 minutes
  File "C:\Users\Admin\Nilesh_Projects\CFA\cfa_ai_app\backend\venv\Lib\site-packages\requests\api.py", line 115, in post
    return request("post", url, data=data, json=json, **kwargs)
  File "C:\Users\Admin\Nilesh_Projects\CFA\cfa_ai_app\backend\venv\Lib\site-packages\requests\api.py", line 59, in request
    return session.request(method=method, url=url, **kwargs)
           ~~~~~~~~~~~~~~~^^^^^^^^^^^^^^^^^^^^^^^^^^^^^^^^^^
  File "C:\Users\Admin\Nilesh_Projects\CFA\cfa_ai_app\backend\venv\Lib\site-packages\requests\sessions.py", line 589, in request
    resp = self.send(prep, **send_kwargs)
  File "C:\Users\Admin\Nilesh_Projects\CFA\cfa_ai_app\backend\venv\Lib\site-packages\requests\sessions.py", line 703, in send
    r = adapter.send(request, **kwargs)
  File "C:\Users\Admin\Nilesh_Projects\CFA\cfa_ai_app\backend\venv\Lib\site-packages\requests\adapters.py", line 713, in send
    raise ReadTimeout(e, request=request)
requests.exceptions.ReadTimeout: HTTPConnectionPool(host='localhost', port=9000): Read timed out. (read timeout=150)

[2025-07-07 00:09:40] Loaded TALLY_URL: http://localhost:9000
[2025-07-07 00:09:42] Sync Data button clicked.
[2025-07-07 00:09:42] Sending test connection POST to http://localhost:9000
[2025-07-07 00:10:15] Test connection response: status=200, text=<ENVELOPE>

 <HEADER>

  <TALLYREQUEST>Import Data</TALLYREQUEST>

 </HEADER>

 <BODY>

  <IMPORTDATA>

   <REQUESTDESC>

    <REPORTNAME>All Masters</REPORTNAME>

    <STATICVARIABLES>

     <SVCURRE
[2025-07-07 00:10:15] Tally connected. Fetching data...
[2025-07-07 00:10:15] Sending data request to http://localhost:9000 with XML: 
    <ENVELOPE>
        <HEADER>
            <TALLYREQUEST>Export Data</TALLYREQUEST>
        </HEAD
[2025-07-07 00:10:23] Data request response: status=200, text=<ENVELOPE>

 <VOUCHERDATE></VOUCHERDATE>

 <VOUCHERTYPE>Sales</VOUCHERTYPE>

 <VOUCHERNUMBER>24-25/01</VOUCHERNUMBER>

 <PARTYNAME>BHS-SONTHOFEN INDIA PRIVATE LIMITED</PARTYNAME>

 <VOUCHERAMOUNT>1067
[2025-07-07 00:10:23] ❌ Failed to parse Tally XML: not well-formed (invalid token): line 91, column 32
Snippet: <ENVELOPE>

 <VOUCHERDATE></VOUCHERDATE>

 <VOUCHERTYPE>Sales</VOUCHERTYPE>

 <VOUCHERNUMBER>24-25/01</VOUCHERNUMBER>

 <PARTYNAME>BHS-SONTHOFEN INDIA PRIVATE LIMITED</PARTYNAME>

 <VOUCHERAMOUNT>1067900</VOUCHERAMOUNT>

 <NARRATIONFIELDEXPORT></NARRATIONFIELDEXPORT>

 <VOUCHERDATE></VOUCHERDATE>

 <VOUCHERTYPE>Sales</VOUCHERTYPE>

 <VOUCHERNUMBER>24-25/02</VOUCHERNUMBER>

 <PARTYNAME>BHS-SONTHOFEN INDIA PRIVATE LIMITED</PARTYNAME>

 <VOUCHERAMOUNT>15659</VOUCHERAMOUNT>

 <NARRATIONFIELDEXPORT><
[2025-07-07 00:14:07] No data fetched from Tally.
[2025-07-07 00:14:09] Sync Data button clicked.
[2025-07-07 00:14:09] Sending test connection POST to http://localhost:9000
[2025-07-07 00:14:17] ❌ Connection failed: ('Connection aborted.', ConnectionResetError(10054, 'An existing connection was forcibly closed by the remote host', None, 10054, None))
Traceback (most recent call last):
  File "C:\Users\Admin\Nilesh_Projects\CFA\cfa_ai_app\backend\venv\Lib\site-packages\urllib3\connectionpool.py", line 787, in urlopen
    response = self._make_request(
        conn,
    ...<10 lines>...
        **response_kw,
    )
  File "C:\Users\Admin\Nilesh_Projects\CFA\cfa_ai_app\backend\venv\Lib\site-packages\urllib3\connectionpool.py", line 534, in _make_request
    response = conn.getresponse()
  File "C:\Users\Admin\Nilesh_Projects\CFA\cfa_ai_app\backend\venv\Lib\site-packages\urllib3\connection.py", line 565, in getresponse
    httplib_response = super().getresponse()
  File "C:\Users\Admin\AppData\Local\Programs\Python\Python313\Lib\http\client.py", line 1430, in getresponse
    response.begin()
    ~~~~~~~~~~~~~~^^
  File "C:\Users\Admin\AppData\Local\Programs\Python\Python313\Lib\http\client.py", line 331, in begin
    version, status, reason = self._read_status()
                              ~~~~~~~~~~~~~~~~~^^
  File "C:\Users\Admin\AppData\Local\Programs\Python\Python313\Lib\http\client.py", line 292, in _read_status
    line = str(self.fp.readline(_MAXLINE + 1), "iso-8859-1")
               ~~~~~~~~~~~~~~~~^^^^^^^^^^^^^^
  File "C:\Users\Admin\AppData\Local\Programs\Python\Python313\Lib\socket.py", line 719, in readinto
    return self._sock.recv_into(b)
           ~~~~~~~~~~~~~~~~~~~~^^^
ConnectionResetError: [WinError 10054] An existing connection was forcibly closed by the remote host

During handling of the above exception, another exception occurred:

Traceback (most recent call last):
  File "C:\Users\Admin\Nilesh_Projects\CFA\cfa_ai_app\backend\venv\Lib\site-packages\requests\adapters.py", line 667, in send
    resp = conn.urlopen(
        method=request.method,
    ...<9 lines>...
        chunked=chunked,
    )
  File "C:\Users\Admin\Nilesh_Projects\CFA\cfa_ai_app\backend\venv\Lib\site-packages\urllib3\connectionpool.py", line 841, in urlopen
    retries = retries.increment(
        method, url, error=new_e, _pool=self, _stacktrace=sys.exc_info()[2]
    )
  File "C:\Users\Admin\Nilesh_Projects\CFA\cfa_ai_app\backend\venv\Lib\site-packages\urllib3\util\retry.py", line 474, in increment
    raise reraise(type(error), error, _stacktrace)
          ~~~~~~~^^^^^^^^^^^^^^^^^^^^^^^^^^^^^^^^^
  File "C:\Users\Admin\Nilesh_Projects\CFA\cfa_ai_app\backend\venv\Lib\site-packages\urllib3\util\util.py", line 38, in reraise
    raise value.with_traceback(tb)
  File "C:\Users\Admin\Nilesh_Projects\CFA\cfa_ai_app\backend\venv\Lib\site-packages\urllib3\connectionpool.py", line 787, in urlopen
    response = self._make_request(
        conn,
    ...<10 lines>...
        **response_kw,
    )
  File "C:\Users\Admin\Nilesh_Projects\CFA\cfa_ai_app\backend\venv\Lib\site-packages\urllib3\connectionpool.py", line 534, in _make_request
    response = conn.getresponse()
  File "C:\Users\Admin\Nilesh_Projects\CFA\cfa_ai_app\backend\venv\Lib\site-packages\urllib3\connection.py", line 565, in getresponse
    httplib_response = super().getresponse()
  File "C:\Users\Admin\AppData\Local\Programs\Python\Python313\Lib\http\client.py", line 1430, in getresponse
    response.begin()
    ~~~~~~~~~~~~~~^^
  File "C:\Users\Admin\AppData\Local\Programs\Python\Python313\Lib\http\client.py", line 331, in begin
    version, status, reason = self._read_status()
                              ~~~~~~~~~~~~~~~~~^^
  File "C:\Users\Admin\AppData\Local\Programs\Python\Python313\Lib\http\client.py", line 292, in _read_status
    line = str(self.fp.readline(_MAXLINE + 1), "iso-8859-1")
               ~~~~~~~~~~~~~~~~^^^^^^^^^^^^^^
  File "C:\Users\Admin\AppData\Local\Programs\Python\Python313\Lib\socket.py", line 719, in readinto
    return self._sock.recv_into(b)
           ~~~~~~~~~~~~~~~~~~~~^^^
urllib3.exceptions.ProtocolError: ('Connection aborted.', ConnectionResetError(10054, 'An existing connection was forcibly closed by the remote host', None, 10054, None))

During handling of the above exception, another exception occurred:

Traceback (most recent call last):
  File "C:\Users\Admin\Nilesh_Projects\CFA\cfa_ai_app\Desktop_tally_sync-agent\tally_connector.py", line 52, in test_tally_connection
    response = requests.post(TALLY_URL, data=test_request, timeout=150)  # 2 minutes
  File "C:\Users\Admin\Nilesh_Projects\CFA\cfa_ai_app\backend\venv\Lib\site-packages\requests\api.py", line 115, in post
    return request("post", url, data=data, json=json, **kwargs)
  File "C:\Users\Admin\Nilesh_Projects\CFA\cfa_ai_app\backend\venv\Lib\site-packages\requests\api.py", line 59, in request
    return session.request(method=method, url=url, **kwargs)
           ~~~~~~~~~~~~~~~^^^^^^^^^^^^^^^^^^^^^^^^^^^^^^^^^^
  File "C:\Users\Admin\Nilesh_Projects\CFA\cfa_ai_app\backend\venv\Lib\site-packages\requests\sessions.py", line 589, in request
    resp = self.send(prep, **send_kwargs)
  File "C:\Users\Admin\Nilesh_Projects\CFA\cfa_ai_app\backend\venv\Lib\site-packages\requests\sessions.py", line 703, in send
    r = adapter.send(request, **kwargs)
  File "C:\Users\Admin\Nilesh_Projects\CFA\cfa_ai_app\backend\venv\Lib\site-packages\requests\adapters.py", line 682, in send
    raise ConnectionError(err, request=request)
requests.exceptions.ConnectionError: ('Connection aborted.', ConnectionResetError(10054, 'An existing connection was forcibly closed by the remote host', None, 10054, None))

[2025-07-07 00:14:18] Tally not connected. Sync aborted.
[2025-07-07 00:16:33] Sync Data button clicked.
[2025-07-07 00:16:33] Sending test connection POST to http://localhost:9000
[2025-07-07 00:16:55] Test connection response: status=200, text=<ENVELOPE>

 <HEADER>

  <TALLYREQUEST>Import Data</TALLYREQUEST>

 </HEADER>

 <BODY>

  <IMPORTDATA>

   <REQUESTDESC>

    <REPORTNAME>All Masters</REPORTNAME>

    <STATICVARIABLES>

     <SVCURRE
[2025-07-07 00:16:55] Tally connected. Fetching data...
[2025-07-07 00:16:55] Sending data request to http://localhost:9000 with XML: 
    <ENVELOPE>
        <HEADER>
            <TALLYREQUEST>Export Data</TALLYREQUEST>
        </HEAD
[2025-07-07 00:17:08] Data request response: status=200, text=<ENVELOPE>

 <VOUCHERDATE></VOUCHERDATE>

 <VOUCHERTYPE>Sales</VOUCHERTYPE>

 <VOUCHERNUMBER>24-25/01</VOUCHERNUMBER>

 <PARTYNAME>BHS-SONTHOFEN INDIA PRIVATE LIMITED</PARTYNAME>

 <VOUCHERAMOUNT>1067
[2025-07-07 00:17:08] ❌ Failed to parse Tally XML: not well-formed (invalid token): line 91, column 32
Snippet: <ENVELOPE>

 <VOUCHERDATE></VOUCHERDATE>

 <VOUCHERTYPE>Sales</VOUCHERTYPE>

 <VOUCHERNUMBER>24-25/01</VOUCHERNUMBER>

 <PARTYNAME>BHS-SONTHOFEN INDIA PRIVATE LIMITED</PARTYNAME>

 <VOUCHERAMOUNT>1067900</VOUCHERAMOUNT>

 <NARRATIONFIELDEXPORT></NARRATIONFIELDEXPORT>

 <VOUCHERDATE></VOUCHERDATE>

 <VOUCHERTYPE>Sales</VOUCHERTYPE>

 <VOUCHERNUMBER>24-25/02</VOUCHERNUMBER>

 <PARTYNAME>BHS-SONTHOFEN INDIA PRIVATE LIMITED</PARTYNAME>

 <VOUCHERAMOUNT>15659</VOUCHERAMOUNT>

 <NARRATIONFIELDEXPORT><
[2025-07-07 00:25:35] No data fetched from Tally.
[2025-07-07 00:25:37] Sync Data button clicked.
[2025-07-07 00:25:37] Sending test connection POST to http://localhost:9000
[2025-07-07 00:26:21] ❌ Connection failed: ('Connection aborted.', ConnectionResetError(10054, 'An existing connection was forcibly closed by the remote host', None, 10054, None))
Traceback (most recent call last):
  File "C:\Users\Admin\Nilesh_Projects\CFA\cfa_ai_app\backend\venv\Lib\site-packages\urllib3\connectionpool.py", line 787, in urlopen
    response = self._make_request(
        conn,
    ...<10 lines>...
        **response_kw,
    )
  File "C:\Users\Admin\Nilesh_Projects\CFA\cfa_ai_app\backend\venv\Lib\site-packages\urllib3\connectionpool.py", line 534, in _make_request
    response = conn.getresponse()
  File "C:\Users\Admin\Nilesh_Projects\CFA\cfa_ai_app\backend\venv\Lib\site-packages\urllib3\connection.py", line 565, in getresponse
    httplib_response = super().getresponse()
  File "C:\Users\Admin\AppData\Local\Programs\Python\Python313\Lib\http\client.py", line 1430, in getresponse
    response.begin()
    ~~~~~~~~~~~~~~^^
  File "C:\Users\Admin\AppData\Local\Programs\Python\Python313\Lib\http\client.py", line 331, in begin
    version, status, reason = self._read_status()
                              ~~~~~~~~~~~~~~~~~^^
  File "C:\Users\Admin\AppData\Local\Programs\Python\Python313\Lib\http\client.py", line 292, in _read_status
    line = str(self.fp.readline(_MAXLINE + 1), "iso-8859-1")
               ~~~~~~~~~~~~~~~~^^^^^^^^^^^^^^
  File "C:\Users\Admin\AppData\Local\Programs\Python\Python313\Lib\socket.py", line 719, in readinto
    return self._sock.recv_into(b)
           ~~~~~~~~~~~~~~~~~~~~^^^
ConnectionResetError: [WinError 10054] An existing connection was forcibly closed by the remote host

During handling of the above exception, another exception occurred:

Traceback (most recent call last):
  File "C:\Users\Admin\Nilesh_Projects\CFA\cfa_ai_app\backend\venv\Lib\site-packages\requests\adapters.py", line 667, in send
    resp = conn.urlopen(
        method=request.method,
    ...<9 lines>...
        chunked=chunked,
    )
  File "C:\Users\Admin\Nilesh_Projects\CFA\cfa_ai_app\backend\venv\Lib\site-packages\urllib3\connectionpool.py", line 841, in urlopen
    retries = retries.increment(
        method, url, error=new_e, _pool=self, _stacktrace=sys.exc_info()[2]
    )
  File "C:\Users\Admin\Nilesh_Projects\CFA\cfa_ai_app\backend\venv\Lib\site-packages\urllib3\util\retry.py", line 474, in increment
    raise reraise(type(error), error, _stacktrace)
          ~~~~~~~^^^^^^^^^^^^^^^^^^^^^^^^^^^^^^^^^
  File "C:\Users\Admin\Nilesh_Projects\CFA\cfa_ai_app\backend\venv\Lib\site-packages\urllib3\util\util.py", line 38, in reraise
    raise value.with_traceback(tb)
  File "C:\Users\Admin\Nilesh_Projects\CFA\cfa_ai_app\backend\venv\Lib\site-packages\urllib3\connectionpool.py", line 787, in urlopen
    response = self._make_request(
        conn,
    ...<10 lines>...
        **response_kw,
    )
  File "C:\Users\Admin\Nilesh_Projects\CFA\cfa_ai_app\backend\venv\Lib\site-packages\urllib3\connectionpool.py", line 534, in _make_request
    response = conn.getresponse()
  File "C:\Users\Admin\Nilesh_Projects\CFA\cfa_ai_app\backend\venv\Lib\site-packages\urllib3\connection.py", line 565, in getresponse
    httplib_response = super().getresponse()
  File "C:\Users\Admin\AppData\Local\Programs\Python\Python313\Lib\http\client.py", line 1430, in getresponse
    response.begin()
    ~~~~~~~~~~~~~~^^
  File "C:\Users\Admin\AppData\Local\Programs\Python\Python313\Lib\http\client.py", line 331, in begin
    version, status, reason = self._read_status()
                              ~~~~~~~~~~~~~~~~~^^
  File "C:\Users\Admin\AppData\Local\Programs\Python\Python313\Lib\http\client.py", line 292, in _read_status
    line = str(self.fp.readline(_MAXLINE + 1), "iso-8859-1")
               ~~~~~~~~~~~~~~~~^^^^^^^^^^^^^^
  File "C:\Users\Admin\AppData\Local\Programs\Python\Python313\Lib\socket.py", line 719, in readinto
    return self._sock.recv_into(b)
           ~~~~~~~~~~~~~~~~~~~~^^^
urllib3.exceptions.ProtocolError: ('Connection aborted.', ConnectionResetError(10054, 'An existing connection was forcibly closed by the remote host', None, 10054, None))

During handling of the above exception, another exception occurred:

Traceback (most recent call last):
  File "C:\Users\Admin\Nilesh_Projects\CFA\cfa_ai_app\Desktop_tally_sync-agent\tally_connector.py", line 52, in test_tally_connection
    response = requests.post(TALLY_URL, data=test_request, timeout=150)  # 2 minutes
  File "C:\Users\Admin\Nilesh_Projects\CFA\cfa_ai_app\backend\venv\Lib\site-packages\requests\api.py", line 115, in post
    return request("post", url, data=data, json=json, **kwargs)
  File "C:\Users\Admin\Nilesh_Projects\CFA\cfa_ai_app\backend\venv\Lib\site-packages\requests\api.py", line 59, in request
    return session.request(method=method, url=url, **kwargs)
           ~~~~~~~~~~~~~~~^^^^^^^^^^^^^^^^^^^^^^^^^^^^^^^^^^
  File "C:\Users\Admin\Nilesh_Projects\CFA\cfa_ai_app\backend\venv\Lib\site-packages\requests\sessions.py", line 589, in request
    resp = self.send(prep, **send_kwargs)
  File "C:\Users\Admin\Nilesh_Projects\CFA\cfa_ai_app\backend\venv\Lib\site-packages\requests\sessions.py", line 703, in send
    r = adapter.send(request, **kwargs)
  File "C:\Users\Admin\Nilesh_Projects\CFA\cfa_ai_app\backend\venv\Lib\site-packages\requests\adapters.py", line 682, in send
    raise ConnectionError(err, request=request)
requests.exceptions.ConnectionError: ('Connection aborted.', ConnectionResetError(10054, 'An existing connection was forcibly closed by the remote host', None, 10054, None))

[2025-07-07 00:27:45] Tally not connected. Sync aborted.
[2025-07-07 00:27:47] Sync Data button clicked.
[2025-07-07 00:27:47] Sending test connection POST to http://localhost:9000
[2025-07-07 00:28:24] Test connection response: status=200, text=<ENVELOPE>

 <HEADER>

  <TALLYREQUEST>Import Data</TALLYREQUEST>

 </HEADER>

 <BODY>

  <IMPORTDATA>

   <REQUESTDESC>

    <REPORTNAME>All Masters</REPORTNAME>

    <STATICVARIABLES>

     <SVCURRE
[2025-07-07 00:28:24] Tally connected. Fetching data...
[2025-07-07 00:28:24] Sending data request to http://localhost:9000 with XML: 
    <ENVELOPE>
        <HEADER>
            <TALLYREQUEST>Export Data</TALLYREQUEST>
        </HEAD
[2025-07-07 00:28:34] Data request response: status=200, text=<ENVELOPE>

 <VOUCHERDATE></VOUCHERDATE>

 <VOUCHERTYPE>Sales</VOUCHERTYPE>

 <VOUCHERNUMBER>24-25/01</VOUCHERNUMBER>

 <PARTYNAME>BHS-SONTHOFEN INDIA PRIVATE LIMITED</PARTYNAME>

 <VOUCHERAMOUNT>1067
[2025-07-07 00:28:34] ❌ Failed to parse Tally XML: not well-formed (invalid token): line 91, column 32
Snippet: <ENVELOPE>

 <VOUCHERDATE></VOUCHERDATE>

 <VOUCHERTYPE>Sales</VOUCHERTYPE>

 <VOUCHERNUMBER>24-25/01</VOUCHERNUMBER>

 <PARTYNAME>BHS-SONTHOFEN INDIA PRIVATE LIMITED</PARTYNAME>

 <VOUCHERAMOUNT>1067900</VOUCHERAMOUNT>

 <NARRATIONFIELDEXPORT></NARRATIONFIELDEXPORT>

 <VOUCHERDATE></VOUCHERDATE>

 <VOUCHERTYPE>Sales</VOUCHERTYPE>

 <VOUCHERNUMBER>24-25/02</VOUCHERNUMBER>

 <PARTYNAME>BHS-SONTHOFEN INDIA PRIVATE LIMITED</PARTYNAME>

 <VOUCHERAMOUNT>15659</VOUCHERAMOUNT>

 <NARRATIONFIELDEXPORT><
[2025-07-07 00:33:04] No data fetched from Tally.
[2025-07-07 00:33:06] Sync Data button clicked.
[2025-07-07 00:33:06] Sending test connection POST to http://localhost:9000
[2025-07-07 00:33:50] ❌ Connection failed: ('Connection aborted.', ConnectionResetError(10054, 'An existing connection was forcibly closed by the remote host', None, 10054, None))
Traceback (most recent call last):
  File "C:\Users\Admin\Nilesh_Projects\CFA\cfa_ai_app\backend\venv\Lib\site-packages\urllib3\connectionpool.py", line 787, in urlopen
    response = self._make_request(
        conn,
    ...<10 lines>...
        **response_kw,
    )
  File "C:\Users\Admin\Nilesh_Projects\CFA\cfa_ai_app\backend\venv\Lib\site-packages\urllib3\connectionpool.py", line 534, in _make_request
    response = conn.getresponse()
  File "C:\Users\Admin\Nilesh_Projects\CFA\cfa_ai_app\backend\venv\Lib\site-packages\urllib3\connection.py", line 565, in getresponse
    httplib_response = super().getresponse()
  File "C:\Users\Admin\AppData\Local\Programs\Python\Python313\Lib\http\client.py", line 1430, in getresponse
    response.begin()
    ~~~~~~~~~~~~~~^^
  File "C:\Users\Admin\AppData\Local\Programs\Python\Python313\Lib\http\client.py", line 331, in begin
    version, status, reason = self._read_status()
                              ~~~~~~~~~~~~~~~~~^^
  File "C:\Users\Admin\AppData\Local\Programs\Python\Python313\Lib\http\client.py", line 292, in _read_status
    line = str(self.fp.readline(_MAXLINE + 1), "iso-8859-1")
               ~~~~~~~~~~~~~~~~^^^^^^^^^^^^^^
  File "C:\Users\Admin\AppData\Local\Programs\Python\Python313\Lib\socket.py", line 719, in readinto
    return self._sock.recv_into(b)
           ~~~~~~~~~~~~~~~~~~~~^^^
ConnectionResetError: [WinError 10054] An existing connection was forcibly closed by the remote host

During handling of the above exception, another exception occurred:

Traceback (most recent call last):
  File "C:\Users\Admin\Nilesh_Projects\CFA\cfa_ai_app\backend\venv\Lib\site-packages\requests\adapters.py", line 667, in send
    resp = conn.urlopen(
        method=request.method,
    ...<9 lines>...
        chunked=chunked,
    )
  File "C:\Users\Admin\Nilesh_Projects\CFA\cfa_ai_app\backend\venv\Lib\site-packages\urllib3\connectionpool.py", line 841, in urlopen
    retries = retries.increment(
        method, url, error=new_e, _pool=self, _stacktrace=sys.exc_info()[2]
    )
  File "C:\Users\Admin\Nilesh_Projects\CFA\cfa_ai_app\backend\venv\Lib\site-packages\urllib3\util\retry.py", line 474, in increment
    raise reraise(type(error), error, _stacktrace)
          ~~~~~~~^^^^^^^^^^^^^^^^^^^^^^^^^^^^^^^^^
  File "C:\Users\Admin\Nilesh_Projects\CFA\cfa_ai_app\backend\venv\Lib\site-packages\urllib3\util\util.py", line 38, in reraise
    raise value.with_traceback(tb)
  File "C:\Users\Admin\Nilesh_Projects\CFA\cfa_ai_app\backend\venv\Lib\site-packages\urllib3\connectionpool.py", line 787, in urlopen
    response = self._make_request(
        conn,
    ...<10 lines>...
        **response_kw,
    )
  File "C:\Users\Admin\Nilesh_Projects\CFA\cfa_ai_app\backend\venv\Lib\site-packages\urllib3\connectionpool.py", line 534, in _make_request
    response = conn.getresponse()
  File "C:\Users\Admin\Nilesh_Projects\CFA\cfa_ai_app\backend\venv\Lib\site-packages\urllib3\connection.py", line 565, in getresponse
    httplib_response = super().getresponse()
  File "C:\Users\Admin\AppData\Local\Programs\Python\Python313\Lib\http\client.py", line 1430, in getresponse
    response.begin()
    ~~~~~~~~~~~~~~^^
  File "C:\Users\Admin\AppData\Local\Programs\Python\Python313\Lib\http\client.py", line 331, in begin
    version, status, reason = self._read_status()
                              ~~~~~~~~~~~~~~~~~^^
  File "C:\Users\Admin\AppData\Local\Programs\Python\Python313\Lib\http\client.py", line 292, in _read_status
    line = str(self.fp.readline(_MAXLINE + 1), "iso-8859-1")
               ~~~~~~~~~~~~~~~~^^^^^^^^^^^^^^
  File "C:\Users\Admin\AppData\Local\Programs\Python\Python313\Lib\socket.py", line 719, in readinto
    return self._sock.recv_into(b)
           ~~~~~~~~~~~~~~~~~~~~^^^
urllib3.exceptions.ProtocolError: ('Connection aborted.', ConnectionResetError(10054, 'An existing connection was forcibly closed by the remote host', None, 10054, None))

During handling of the above exception, another exception occurred:

Traceback (most recent call last):
  File "C:\Users\Admin\Nilesh_Projects\CFA\cfa_ai_app\Desktop_tally_sync-agent\tally_connector.py", line 52, in test_tally_connection
    response = requests.post(TALLY_URL, data=test_request, timeout=150)  # 2 minutes
  File "C:\Users\Admin\Nilesh_Projects\CFA\cfa_ai_app\backend\venv\Lib\site-packages\requests\api.py", line 115, in post
    return request("post", url, data=data, json=json, **kwargs)
  File "C:\Users\Admin\Nilesh_Projects\CFA\cfa_ai_app\backend\venv\Lib\site-packages\requests\api.py", line 59, in request
    return session.request(method=method, url=url, **kwargs)
           ~~~~~~~~~~~~~~~^^^^^^^^^^^^^^^^^^^^^^^^^^^^^^^^^^
  File "C:\Users\Admin\Nilesh_Projects\CFA\cfa_ai_app\backend\venv\Lib\site-packages\requests\sessions.py", line 589, in request
    resp = self.send(prep, **send_kwargs)
  File "C:\Users\Admin\Nilesh_Projects\CFA\cfa_ai_app\backend\venv\Lib\site-packages\requests\sessions.py", line 703, in send
    r = adapter.send(request, **kwargs)
  File "C:\Users\Admin\Nilesh_Projects\CFA\cfa_ai_app\backend\venv\Lib\site-packages\requests\adapters.py", line 682, in send
    raise ConnectionError(err, request=request)
requests.exceptions.ConnectionError: ('Connection aborted.', ConnectionResetError(10054, 'An existing connection was forcibly closed by the remote host', None, 10054, None))

[2025-07-07 00:33:51] Tally not connected. Sync aborted.
[2025-07-07 00:38:35] Sync Data button clicked.
[2025-07-07 00:38:35] Sending test connection POST to http://localhost:9000
[2025-07-07 00:38:59] Test connection response: status=200, text=<ENVELOPE>

 <HEADER>

  <TALLYREQUEST>Import Data</TALLYREQUEST>

 </HEADER>

 <BODY>

  <IMPORTDATA>

   <REQUESTDESC>

    <REPORTNAME>All Masters</REPORTNAME>

    <STATICVARIABLES>

     <SVCURRE
[2025-07-07 00:38:59] Tally connected. Fetching data...
[2025-07-07 00:38:59] Sending data request to http://localhost:9000 with XML: 
    <ENVELOPE>
        <HEADER>
            <TALLYREQUEST>Export Data</TALLYREQUEST>
        </HEAD
[2025-07-07 00:41:00] ❌ Timeout while connecting to Tally.
[2025-07-07 00:57:26] Loaded TALLY_URL: http://localhost:9000
[2025-07-07 00:57:28] Sync Data button clicked.
[2025-07-07 00:57:28] Sending test connection POST to http://localhost:9000
[2025-07-07 00:57:49] Test connection response: status=200, text=<ENVELOPE>

 <HEADER>

  <TALLYREQUEST>Import Data</TALLYREQUEST>

 </HEADER>

 <BODY>

  <IMPORTDATA>

   <REQUESTDESC>

    <REPORTNAME>All Masters</REPORTNAME>

    <STATICVARIABLES>

     <SVCURRE
[2025-07-07 00:57:49] Tally connected. Fetching data...
[2025-07-07 00:57:49] Sending data request to http://localhost:9000 with XML: 
    <ENVELOPE>
        <HEADER>
            <TALLYREQUEST>Export Data</TALLYREQUEST>
        </HEAD
[2025-07-07 00:58:15] ❌ Error fetching data from Tally: ('Connection aborted.', ConnectionResetError(10054, 'An existing connection was forcibly closed by the remote host', None, 10054, None))
[2025-07-07 00:58:18] No data fetched from Tally.
[2025-07-07 01:25:10] Loaded TALLY_URL: http://localhost:9000
[2025-07-07 01:30:40] Loaded TALLY_URL: http://localhost:9000
[2025-07-07 01:31:15] Sync Data button clicked.
[2025-07-07 01:31:15] Sending test connection POST to http://localhost:9000
[2025-07-07 01:31:38] Test connection response: status=200, text=<ENVELOPE>

 <HEADER>

  <TALLYREQUEST>Import Data</TALLYREQUEST>

 </HEADER>

 <BODY>

  <IMPORTDATA>

   <REQUESTDESC>

    <REPORTNAME>All Masters</REPORTNAME>

    <STATICVARIABLES>

     <SVCURRE
[2025-07-07 01:31:38] Sending data request to http://localhost:9000 with XML: 
    <ENVELOPE>
        <HEADER>
            <TALLYREQUEST>Export Data</TALLYREQUEST>
        </HEAD
[2025-07-07 01:31:58] ❌ Error fetching data from Tally: ('Connection aborted.', ConnectionResetError(10054, 'An existing connection was forcibly closed by the remote host', None, 10054, None))
[2025-07-07 01:32:00] ❌ Error extracting company name: 'NoneType' object is not subscriptable
[2025-07-07 01:32:00] Tally connected. Fetching data...
[2025-07-07 01:32:00] Sending data request to http://localhost:9000 with XML: 
    <ENVELOPE>
        <HEADER>
            <TALLYREQUEST>Export Data</TALLYREQUEST>
        </HEAD
[2025-07-07 01:32:07] ❌ Error fetching data from Tally: HTTPConnectionPool(host='localhost', port=9000): Max retries exceeded with url: / (Caused by NewConnectionError('<urllib3.connection.HTTPConnection object at 0x0000025A15C45BD0>: Failed to establish a new connection: [WinError 10061] No connection could be made because the target machine actively refused it'))
[2025-07-07 01:32:16] No data fetched from Tally.
[2025-07-07 01:35:20] ✅ API connector session closed
[2025-07-07 01:35:27] Loaded TALLY_URL: http://localhost:9000
[2025-07-07 01:35:38] Sync Data button clicked.
[2025-07-07 01:35:38] Sending test connection POST to http://localhost:9000
[2025-07-07 01:36:07] Test connection response: status=200, text=<ENVELOPE>

 <HEADER>

  <TALLYREQUEST>Import Data</TALLYREQUEST>

 </HEADER>

 <BODY>

  <IMPORTDATA>

   <REQUESTDESC>

    <REPORTNAME>All Masters</REPORTNAME>

    <STATICVARIABLES>

     <SVCURRE
[2025-07-07 01:36:07] Sending data request to http://localhost:9000 with XML: 
    <ENVELOPE>
        <HEADER>
            <TALLYREQUEST>Export Data</TALLYREQUEST>
        </HEAD
[2025-07-07 01:38:09] ❌ Timeout while connecting to Tally.
[2025-07-07 01:44:12] ❌ Error extracting company name: 'NoneType' object is not subscriptable
[2025-07-07 01:44:13] Tally connected. Fetching data...
[2025-07-07 01:44:13] Sending data request to http://localhost:9000 with XML: 
    <ENVELOPE>
        <HEADER>
            <TALLYREQUEST>Export Data</TALLYREQUEST>
        </HEAD
[2025-07-07 01:44:20] ✅ API connector session closed
[2025-07-07 01:44:23] Loaded TALLY_URL: http://localhost:9000
[2025-07-07 01:44:29] Sync Data button clicked.
[2025-07-07 01:44:29] Sending test connection POST to http://localhost:9000
[2025-07-07 01:45:38] ❌ Connection failed: ('Connection aborted.', ConnectionResetError(10054, 'An existing connection was forcibly closed by the remote host', None, 10054, None))
Traceback (most recent call last):
  File "C:\Users\Admin\Nilesh_Projects\CFA\cfa_ai_app\backend\venv\Lib\site-packages\urllib3\connectionpool.py", line 787, in urlopen
    response = self._make_request(
        conn,
    ...<10 lines>...
        **response_kw,
    )
  File "C:\Users\Admin\Nilesh_Projects\CFA\cfa_ai_app\backend\venv\Lib\site-packages\urllib3\connectionpool.py", line 534, in _make_request
    response = conn.getresponse()
  File "C:\Users\Admin\Nilesh_Projects\CFA\cfa_ai_app\backend\venv\Lib\site-packages\urllib3\connection.py", line 565, in getresponse
    httplib_response = super().getresponse()
  File "C:\Users\Admin\AppData\Local\Programs\Python\Python313\Lib\http\client.py", line 1430, in getresponse
    response.begin()
    ~~~~~~~~~~~~~~^^
  File "C:\Users\Admin\AppData\Local\Programs\Python\Python313\Lib\http\client.py", line 331, in begin
    version, status, reason = self._read_status()
                              ~~~~~~~~~~~~~~~~~^^
  File "C:\Users\Admin\AppData\Local\Programs\Python\Python313\Lib\http\client.py", line 292, in _read_status
    line = str(self.fp.readline(_MAXLINE + 1), "iso-8859-1")
               ~~~~~~~~~~~~~~~~^^^^^^^^^^^^^^
  File "C:\Users\Admin\AppData\Local\Programs\Python\Python313\Lib\socket.py", line 719, in readinto
    return self._sock.recv_into(b)
           ~~~~~~~~~~~~~~~~~~~~^^^
ConnectionResetError: [WinError 10054] An existing connection was forcibly closed by the remote host

During handling of the above exception, another exception occurred:

Traceback (most recent call last):
  File "C:\Users\Admin\Nilesh_Projects\CFA\cfa_ai_app\backend\venv\Lib\site-packages\requests\adapters.py", line 667, in send
    resp = conn.urlopen(
        method=request.method,
    ...<9 lines>...
        chunked=chunked,
    )
  File "C:\Users\Admin\Nilesh_Projects\CFA\cfa_ai_app\backend\venv\Lib\site-packages\urllib3\connectionpool.py", line 841, in urlopen
    retries = retries.increment(
        method, url, error=new_e, _pool=self, _stacktrace=sys.exc_info()[2]
    )
  File "C:\Users\Admin\Nilesh_Projects\CFA\cfa_ai_app\backend\venv\Lib\site-packages\urllib3\util\retry.py", line 474, in increment
    raise reraise(type(error), error, _stacktrace)
          ~~~~~~~^^^^^^^^^^^^^^^^^^^^^^^^^^^^^^^^^
  File "C:\Users\Admin\Nilesh_Projects\CFA\cfa_ai_app\backend\venv\Lib\site-packages\urllib3\util\util.py", line 38, in reraise
    raise value.with_traceback(tb)
  File "C:\Users\Admin\Nilesh_Projects\CFA\cfa_ai_app\backend\venv\Lib\site-packages\urllib3\connectionpool.py", line 787, in urlopen
    response = self._make_request(
        conn,
    ...<10 lines>...
        **response_kw,
    )
  File "C:\Users\Admin\Nilesh_Projects\CFA\cfa_ai_app\backend\venv\Lib\site-packages\urllib3\connectionpool.py", line 534, in _make_request
    response = conn.getresponse()
  File "C:\Users\Admin\Nilesh_Projects\CFA\cfa_ai_app\backend\venv\Lib\site-packages\urllib3\connection.py", line 565, in getresponse
    httplib_response = super().getresponse()
  File "C:\Users\Admin\AppData\Local\Programs\Python\Python313\Lib\http\client.py", line 1430, in getresponse
    response.begin()
    ~~~~~~~~~~~~~~^^
  File "C:\Users\Admin\AppData\Local\Programs\Python\Python313\Lib\http\client.py", line 331, in begin
    version, status, reason = self._read_status()
                              ~~~~~~~~~~~~~~~~~^^
  File "C:\Users\Admin\AppData\Local\Programs\Python\Python313\Lib\http\client.py", line 292, in _read_status
    line = str(self.fp.readline(_MAXLINE + 1), "iso-8859-1")
               ~~~~~~~~~~~~~~~~^^^^^^^^^^^^^^
  File "C:\Users\Admin\AppData\Local\Programs\Python\Python313\Lib\socket.py", line 719, in readinto
    return self._sock.recv_into(b)
           ~~~~~~~~~~~~~~~~~~~~^^^
urllib3.exceptions.ProtocolError: ('Connection aborted.', ConnectionResetError(10054, 'An existing connection was forcibly closed by the remote host', None, 10054, None))

During handling of the above exception, another exception occurred:

Traceback (most recent call last):
  File "C:\Users\Admin\Nilesh_Projects\CFA\cfa_ai_app\Desktop_tally_sync-agent\tally_connector.py", line 54, in test_tally_connection
    response = requests.post(TALLY_URL, data=test_request, timeout=150)
  File "C:\Users\Admin\Nilesh_Projects\CFA\cfa_ai_app\backend\venv\Lib\site-packages\requests\api.py", line 115, in post
    return request("post", url, data=data, json=json, **kwargs)
  File "C:\Users\Admin\Nilesh_Projects\CFA\cfa_ai_app\backend\venv\Lib\site-packages\requests\api.py", line 59, in request
    return session.request(method=method, url=url, **kwargs)
           ~~~~~~~~~~~~~~~^^^^^^^^^^^^^^^^^^^^^^^^^^^^^^^^^^
  File "C:\Users\Admin\Nilesh_Projects\CFA\cfa_ai_app\backend\venv\Lib\site-packages\requests\sessions.py", line 589, in request
    resp = self.send(prep, **send_kwargs)
  File "C:\Users\Admin\Nilesh_Projects\CFA\cfa_ai_app\backend\venv\Lib\site-packages\requests\sessions.py", line 703, in send
    r = adapter.send(request, **kwargs)
  File "C:\Users\Admin\Nilesh_Projects\CFA\cfa_ai_app\backend\venv\Lib\site-packages\requests\adapters.py", line 682, in send
    raise ConnectionError(err, request=request)
requests.exceptions.ConnectionError: ('Connection aborted.', ConnectionResetError(10054, 'An existing connection was forcibly closed by the remote host', None, 10054, None))

[2025-07-07 11:55:11] Tally not connected. Sync aborted.
[2025-07-07 11:55:13] Sync Data button clicked.
[2025-07-07 11:55:13] Sending test connection POST to http://localhost:9000
[2025-07-07 11:55:38] Test connection response: status=200, text=<ENVELOPE>

 <HEADER>

  <TALLYREQUEST>Import Data</TALLYREQUEST>

 </HEADER>

 <BODY>

  <IMPORTDATA>

   <REQUESTDESC>

    <REPORTNAME>All Masters</REPORTNAME>

    <STATICVARIABLES>

     <SVCURRE
[2025-07-07 11:55:38] Sending data request to http://localhost:9000 with XML: 
    <ENVELOPE>
        <HEADER>
            <TALLYREQUEST>Export Data</TALLYREQUEST>
        </HEAD
[2025-07-07 11:56:32] ❌ Error fetching data from Tally: ('Connection aborted.', ConnectionResetError(10054, 'An existing connection was forcibly closed by the remote host', None, 10054, None))
[2025-07-07 17:07:11] ❌ Error extracting company name: 'NoneType' object is not subscriptable
[2025-07-07 17:07:11] Tally connected. Fetching data...
[2025-07-07 17:07:11] Sending data request to http://localhost:9000 with XML: 
    <ENVELOPE>
        <HEADER>
            <TALLYREQUEST>Export Data</TALLYREQUEST>
        </HEAD
[2025-07-07 17:07:16] ❌ Error fetching data from Tally: HTTPConnectionPool(host='localhost', port=9000): Max retries exceeded with url: / (Caused by NewConnectionError('<urllib3.connection.HTTPConnection object at 0x0000014458B8A780>: Failed to establish a new connection: [WinError 10061] No connection could be made because the target machine actively refused it'))
[2025-07-07 17:07:20] No data fetched from Tally.
[2025-07-07 17:08:12] Sync Data button clicked.
[2025-07-07 17:08:12] Sending test connection POST to http://localhost:9000
[2025-07-07 17:08:16] ✅ API connector session closed
[2025-07-07 17:08:19] Loaded TALLY_URL: http://localhost:9000
[2025-07-07 17:08:24] Sync Data button clicked.
[2025-07-07 17:08:24] Sending test connection POST to http://localhost:9000
[2025-07-07 17:08:57] Test connection response: status=200, text=<ENVELOPE>

 <HEADER>

  <TALLYREQUEST>Import Data</TALLYREQUEST>

 </HEADER>

 <BODY>

  <IMPORTDATA>

   <REQUESTDESC>

    <REPORTNAME>All Masters</REPORTNAME>

    <STATICVARIABLES>

     <SVCURRE
[2025-07-07 17:08:57] Sending data request to http://localhost:9000 with XML: 
    <ENVELOPE>
        <HEADER>
            <TALLYREQUEST>Export Data</TALLYREQUEST>
        </HEAD
[2025-07-07 17:09:46] ❌ Error fetching data from Tally: ('Connection aborted.', ConnectionResetError(10054, 'An existing connection was forcibly closed by the remote host', None, 10054, None))
[2025-07-07 17:09:50] ❌ Error extracting company name: 'NoneType' object is not subscriptable
[2025-07-07 17:09:50] Tally connected. Fetching data...
[2025-07-07 17:09:50] Sending data request to http://localhost:9000 with XML: 
    <ENVELOPE>
        <HEADER>
            <TALLYREQUEST>Export Data</TALLYREQUEST>
        </HEAD
[2025-07-07 17:09:55] ❌ Error fetching data from Tally: HTTPConnectionPool(host='localhost', port=9000): Max retries exceeded with url: / (Caused by NewConnectionError('<urllib3.connection.HTTPConnection object at 0x000001D4B9B55BD0>: Failed to establish a new connection: [WinError 10061] No connection could be made because the target machine actively refused it'))
[2025-07-07 17:09:58] No data fetched from Tally.
[2025-07-07 18:10:01] ✅ API connector session closed
[2025-07-07 18:10:03] Loaded TALLY_URL: http://localhost:9000
[2025-07-07 18:10:09] Sync Data button clicked.
[2025-07-07 18:10:09] Testing connection to http://localhost:9000
[2025-07-07 18:10:09] Test response: status=200, content_length=105
[2025-07-07 18:10:09] Tally returned error: <RESPONSE>

 <LINEERROR>Could not find Report &apos;Company Information&apos;!</LINEERROR>

</RESPONSE>


[2025-07-07 18:10:10] Tally not connected. Sync aborted.
[2025-07-07 18:10:15] Sync Data button clicked.
[2025-07-07 18:10:15] Testing connection to http://localhost:9000
[2025-07-07 18:10:15] Test response: status=200, content_length=105
[2025-07-07 18:10:15] Tally returned error: <RESPONSE>

 <LINEERROR>Could not find Report &apos;Company Information&apos;!</LINEERROR>

</RESPONSE>


[2025-07-07 18:10:18] Tally not connected. Sync aborted.
[2025-07-07 18:10:28] Sync Data button clicked.
[2025-07-07 18:10:28] Testing connection to http://localhost:9000
[2025-07-07 18:10:28] Test response: status=200, content_length=105
[2025-07-07 18:10:28] Tally returned error: <RESPONSE>

 <LINEERROR>Could not find Report &apos;Company Information&apos;!</LINEERROR>

</RESPONSE>


[2025-07-07 18:10:29] Tally not connected. Sync aborted.
[2025-07-07 18:12:42] Sync Data button clicked.
[2025-07-07 18:12:43] Testing connection to http://localhost:9000
[2025-07-07 18:12:43] Test response: status=200, content_length=105
[2025-07-07 18:12:43] Tally returned error: <RESPONSE>

 <LINEERROR>Could not find Report &apos;Company Information&apos;!</LINEERROR>

</RESPONSE>


[2025-07-07 18:12:44] Tally not connected. Sync aborted.
[2025-07-07 18:12:46] ✅ API connector session closed
[2025-07-07 18:13:06] Loaded TALLY_URL: http://localhost:9000
[2025-07-07 18:13:09] Sync Data button clicked.
[2025-07-07 18:13:09] Testing connection to http://localhost:9000
[2025-07-07 18:13:09] Test response: status=200, content_length=103
[2025-07-07 18:13:09] Tally returned error: <RESPONSE>

 <LINEERROR>Could not find Report &apos;List of Companies&apos;!</LINEERROR>

</RESPONSE>


[2025-07-07 18:13:13] Tally not connected. Sync aborted.
[2025-07-07 18:13:15] Sync Data button clicked.
[2025-07-07 18:13:15] Testing connection to http://localhost:9000
[2025-07-07 18:13:15] Test response: status=200, content_length=103
[2025-07-07 18:13:15] Tally returned error: <RESPONSE>

 <LINEERROR>Could not find Report &apos;List of Companies&apos;!</LINEERROR>

</RESPONSE>


[2025-07-07 18:13:17] Tally not connected. Sync aborted.
[2025-07-07 18:15:34] ✅ API connector session closed
[2025-07-07 18:15:36] Loaded TALLY_URL: http://localhost:9000
[2025-07-07 18:15:38] Sync Data button clicked.
[2025-07-07 18:15:38] Testing connection to http://localhost:9000
[2025-07-07 18:16:06] Test response: status=200, content_length=80165602
[2025-07-07 18:16:07] Tally returned error: <ENVELOPE>

 <HEADER>

  <TALLYREQUEST>Import Data</TALLYREQUEST>

 </HEADER>

 <BODY>

  <IMPORTDATA>

   <REQUESTDESC>

    <REPORTNAME>All Masters</REPORTNAME>

    <STATICVARIABLES>

     <SVCURRE
[2025-07-07 18:20:17] Tally not connected. Sync aborted.
[2025-07-07 18:22:07] ✅ API connector session closed
[2025-07-07 18:22:08] Loaded TALLY_URL: http://localhost:9000
[2025-07-07 18:22:10] Sync Data button clicked.
[2025-07-07 18:22:10] Testing connection to http://localhost:9000
[2025-07-07 18:22:40] Test response: status=200, content_length=80165602
[2025-07-07 18:22:40] Tally returned error: <ENVELOPE>

 <HEADER>

  <TALLYREQUEST>Import Data</TALLYREQUEST>

 </HEADER>

 <BODY>

  <IMPORTDATA>

   <REQUESTDESC>

    <REPORTNAME>All Masters</REPORTNAME>

    <STATICVARIABLES>

     <SVCURRE
[2025-07-07 18:25:29] Tally not connected. Sync aborted.
[2025-07-07 18:32:57] Sync Data button clicked.
[2025-07-07 18:32:57] Testing connection to http://localhost:9000
[2025-07-07 18:33:20] Test response: status=200, content_length=80168570
[2025-07-07 18:33:20] Tally returned error: <ENVELOPE>

 <HEADER>

  <TALLYREQUEST>Import Data</TALLYREQUEST>

 </HEADER>

 <BODY>

  <IMPORTDATA>

   <REQUESTDESC>

    <REPORTNAME>All Masters</REPORTNAME>

    <STATICVARIABLES>

     <SVCURRE
[2025-07-07 18:34:08] Tally not connected. Sync aborted.
[2025-07-07 18:34:10] ✅ API connector session closed
[2025-07-07 18:34:15] Loaded TALLY_URL: http://localhost:9000
[2025-07-07 18:34:18] Sync Data button clicked.
[2025-07-07 18:34:18] Testing connection to http://localhost:9000
[2025-07-07 18:34:18] Test response: status=200, content_length=2725497
[2025-07-07 18:34:19] Tally returned error: <ENVELOPE>

 <HEADER>

  <TALLYREQUEST>Import Data</TALLYREQUEST>

 </HEADER>

 <BODY>

  <IMPORTDATA>

   <REQUESTDESC>

    <REPORTNAME>All Masters</REPORTNAME>

    <STATICVARIABLES>

     <SVCURRE
[2025-07-07 18:34:21] Tally not connected. Sync aborted.
[2025-07-07 18:35:06] ✅ API connector session closed
[2025-07-07 18:35:08] Loaded TALLY_URL: http://localhost:9000
[2025-07-07 18:35:10] Sync Data button clicked.
[2025-07-07 18:35:10] Sending test connection POST to http://localhost:9000
[2025-07-07 18:36:33] Test connection response: status=200, text=<ENVELOPE>

 <HEADER>

  <TALLYREQUEST>Import Data</TALLYREQUEST>

 </HEADER>

 <BODY>

  <IMPORTDATA>

   <REQUESTDESC>

    <REPORTNAME>All Masters</REPORTNAME>

    <STATICVARIABLES>

     <SVCURRE
[2025-07-07 18:36:33] Sending data request to http://localhost:9000 with XML: 
    <ENVELOPE>
        <HEADER>
            <TALLYREQUEST>Export Data</TALLYREQUEST>
        </HEAD
[2025-07-07 18:41:55] ❌ Timeout while connecting to Tally.
[2025-07-07 18:54:23] ❌ Error extracting company name: 'NoneType' object is not subscriptable
[2025-07-07 18:54:23] Tally connected. Fetching data...
[2025-07-07 18:54:23] Sending data request to http://localhost:9000 with XML: 
    <ENVELOPE>
        <HEADER>
            <TALLYREQUEST>Export Data</TALLYREQUEST>
        </HEAD
[2025-07-07 18:54:29] ✅ API connector session closed
[2025-07-07 18:54:31] Loaded TALLY_URL: http://localhost:9000
[2025-07-07 18:54:33] Sync Data button clicked.
[2025-07-07 18:54:33] Sending test connection POST to http://localhost:9000
[2025-07-07 18:57:15] ❌ Connection failed: HTTPConnectionPool(host='localhost', port=9000): Read timed out. (read timeout=150)
Traceback (most recent call last):
  File "C:\Users\Admin\Nilesh_Projects\CFA\cfa_ai_app\backend\venv\Lib\site-packages\urllib3\connectionpool.py", line 534, in _make_request
    response = conn.getresponse()
  File "C:\Users\Admin\Nilesh_Projects\CFA\cfa_ai_app\backend\venv\Lib\site-packages\urllib3\connection.py", line 565, in getresponse
    httplib_response = super().getresponse()
  File "C:\Users\Admin\AppData\Local\Programs\Python\Python313\Lib\http\client.py", line 1430, in getresponse
    response.begin()
    ~~~~~~~~~~~~~~^^
  File "C:\Users\Admin\AppData\Local\Programs\Python\Python313\Lib\http\client.py", line 331, in begin
    version, status, reason = self._read_status()
                              ~~~~~~~~~~~~~~~~~^^
  File "C:\Users\Admin\AppData\Local\Programs\Python\Python313\Lib\http\client.py", line 292, in _read_status
    line = str(self.fp.readline(_MAXLINE + 1), "iso-8859-1")
               ~~~~~~~~~~~~~~~~^^^^^^^^^^^^^^
  File "C:\Users\Admin\AppData\Local\Programs\Python\Python313\Lib\socket.py", line 719, in readinto
    return self._sock.recv_into(b)
           ~~~~~~~~~~~~~~~~~~~~^^^
TimeoutError: timed out

The above exception was the direct cause of the following exception:

Traceback (most recent call last):
  File "C:\Users\Admin\Nilesh_Projects\CFA\cfa_ai_app\backend\venv\Lib\site-packages\requests\adapters.py", line 667, in send
    resp = conn.urlopen(
        method=request.method,
    ...<9 lines>...
        chunked=chunked,
    )
  File "C:\Users\Admin\Nilesh_Projects\CFA\cfa_ai_app\backend\venv\Lib\site-packages\urllib3\connectionpool.py", line 841, in urlopen
    retries = retries.increment(
        method, url, error=new_e, _pool=self, _stacktrace=sys.exc_info()[2]
    )
  File "C:\Users\Admin\Nilesh_Projects\CFA\cfa_ai_app\backend\venv\Lib\site-packages\urllib3\util\retry.py", line 474, in increment
    raise reraise(type(error), error, _stacktrace)
          ~~~~~~~^^^^^^^^^^^^^^^^^^^^^^^^^^^^^^^^^
  File "C:\Users\Admin\Nilesh_Projects\CFA\cfa_ai_app\backend\venv\Lib\site-packages\urllib3\util\util.py", line 39, in reraise
    raise value
  File "C:\Users\Admin\Nilesh_Projects\CFA\cfa_ai_app\backend\venv\Lib\site-packages\urllib3\connectionpool.py", line 787, in urlopen
    response = self._make_request(
        conn,
    ...<10 lines>...
        **response_kw,
    )
  File "C:\Users\Admin\Nilesh_Projects\CFA\cfa_ai_app\backend\venv\Lib\site-packages\urllib3\connectionpool.py", line 536, in _make_request
    self._raise_timeout(err=e, url=url, timeout_value=read_timeout)
    ~~~~~~~~~~~~~~~~~~~^^^^^^^^^^^^^^^^^^^^^^^^^^^^^^^^^^^^^^^^^^^^
  File "C:\Users\Admin\Nilesh_Projects\CFA\cfa_ai_app\backend\venv\Lib\site-packages\urllib3\connectionpool.py", line 367, in _raise_timeout
    raise ReadTimeoutError(
        self, url, f"Read timed out. (read timeout={timeout_value})"
    ) from err
urllib3.exceptions.ReadTimeoutError: HTTPConnectionPool(host='localhost', port=9000): Read timed out. (read timeout=150)

During handling of the above exception, another exception occurred:

Traceback (most recent call last):
  File "C:\Users\Admin\Nilesh_Projects\CFA\cfa_ai_app\Desktop_tally_sync-agent\tally_connector.py", line 54, in test_tally_connection
    response = requests.post(TALLY_URL, data=test_request, timeout=150)
  File "C:\Users\Admin\Nilesh_Projects\CFA\cfa_ai_app\backend\venv\Lib\site-packages\requests\api.py", line 115, in post
    return request("post", url, data=data, json=json, **kwargs)
  File "C:\Users\Admin\Nilesh_Projects\CFA\cfa_ai_app\backend\venv\Lib\site-packages\requests\api.py", line 59, in request
    return session.request(method=method, url=url, **kwargs)
           ~~~~~~~~~~~~~~~^^^^^^^^^^^^^^^^^^^^^^^^^^^^^^^^^^
  File "C:\Users\Admin\Nilesh_Projects\CFA\cfa_ai_app\backend\venv\Lib\site-packages\requests\sessions.py", line 589, in request
    resp = self.send(prep, **send_kwargs)
  File "C:\Users\Admin\Nilesh_Projects\CFA\cfa_ai_app\backend\venv\Lib\site-packages\requests\sessions.py", line 703, in send
    r = adapter.send(request, **kwargs)
  File "C:\Users\Admin\Nilesh_Projects\CFA\cfa_ai_app\backend\venv\Lib\site-packages\requests\adapters.py", line 713, in send
    raise ReadTimeout(e, request=request)
requests.exceptions.ReadTimeout: HTTPConnectionPool(host='localhost', port=9000): Read timed out. (read timeout=150)

[2025-07-07 18:58:38] Tally not connected. Sync aborted.
[2025-07-07 18:59:57] ✅ API connector session closed
[2025-07-07 18:59:59] Loaded TALLY_URL: http://localhost:9000
[2025-07-07 19:00:02] Sync Data button clicked.
[2025-07-07 19:00:02] Sending test connection POST to http://localhost:9000
[2025-07-07 19:00:24] Test connection response: status=200, text=<ENVELOPE>

 <HEADER>

  <TALLYREQUEST>Import Data</TALLYREQUEST>

 </HEADER>

 <BODY>

  <IMPORTDATA>

   <REQUESTDESC>

    <REPORTNAME>All Masters</REPORTNAME>

    <STATICVARIABLES>

     <SVCURRE
[2025-07-07 19:00:24] Sending data request to http://localhost:9000 with XML: 
    <ENVELOPE>
        <HEADER>
            <TALLYREQUEST>Export Data</TALLYREQUEST>
        </HEAD
[2025-07-07 19:01:48] ❌ Error fetching data from Tally: ('Connection aborted.', ConnectionResetError(10054, 'An existing connection was forcibly closed by the remote host', None, 10054, None))
[2025-07-07 19:01:49] ❌ Error extracting company name: 'NoneType' object is not subscriptable
[2025-07-07 19:01:49] Tally connected. Fetching data...
[2025-07-07 19:01:49] Sending data request to http://localhost:9000 with XML: 
    <ENVELOPE>
        <HEADER>
            <TALLYREQUEST>Export Data</TALLYREQUEST>
        </HEAD
[2025-07-07 19:01:54] ❌ Error fetching data from Tally: HTTPConnectionPool(host='localhost', port=9000): Max retries exceeded with url: / (Caused by NewConnectionError('<urllib3.connection.HTTPConnection object at 0x0000020ADE8A5BD0>: Failed to establish a new connection: [WinError 10061] No connection could be made because the target machine actively refused it'))
[2025-07-07 19:01:58] No data fetched from Tally.
[2025-07-07 19:04:28] Sync Data button clicked.
[2025-07-07 19:04:28] Sending test connection POST to http://localhost:9000
[2025-07-07 19:04:52] Test connection response: status=200, text=<ENVELOPE>

 <HEADER>

  <TALLYREQUEST>Import Data</TALLYREQUEST>

 </HEADER>

 <BODY>

  <IMPORTDATA>

   <REQUESTDESC>

    <REPORTNAME>All Masters</REPORTNAME>

    <STATICVARIABLES>

     <SVCURRE
[2025-07-07 19:04:52] Sending data request to http://localhost:9000 with XML: 
    <ENVELOPE>
        <HEADER>
            <TALLYREQUEST>Export Data</TALLYREQUEST>
        </HEAD
[2025-07-07 19:06:54] ❌ Timeout while connecting to Tally.
[2025-07-07 19:20:41] ❌ Error extracting company name: 'NoneType' object is not subscriptable
[2025-07-07 19:20:41] Tally connected. Fetching data...
[2025-07-07 19:20:41] Sending data request to http://localhost:9000 with XML: 
    <ENVELOPE>
        <HEADER>
            <TALLYREQUEST>Export Data</TALLYREQUEST>
        </HEAD
[2025-07-07 19:20:46] ❌ Error fetching data from Tally: HTTPConnectionPool(host='localhost', port=9000): Max retries exceeded with url: / (Caused by NewConnectionError('<urllib3.connection.HTTPConnection object at 0x0000020ADE862570>: Failed to establish a new connection: [WinError 10061] No connection could be made because the target machine actively refused it'))
[2025-07-07 19:20:52] No data fetched from Tally.
[2025-07-07 19:27:40] ✅ API connector session closed
[2025-07-07 19:27:42] Loaded TALLY_URL: http://localhost:9000
[2025-07-07 19:27:44] Sync Data button clicked.
[2025-07-07 19:27:44] Sending test connection POST to http://localhost:9000
[2025-07-07 19:28:07] Test connection response: status=200, text=<ENVELOPE>

 <HEADER>

  <TALLYREQUEST>Import Data</TALLYREQUEST>

 </HEADER>

 <BODY>

  <IMPORTDATA>

   <REQUESTDESC>

    <REPORTNAME>All Masters</REPORTNAME>

    <STATICVARIABLES>

     <SVCURRE
[2025-07-07 19:28:07] Sending data request to http://localhost:9000 with XML: 
    <ENVELOPE>
        <HEADER>
            <TALLYREQUEST>Export Data</TALLYREQUEST>
        </HEAD
[2025-07-07 19:29:11] ❌ Error fetching data from Tally: ('Connection aborted.', ConnectionResetError(10054, 'An existing connection was forcibly closed by the remote host', None, 10054, None))
[2025-07-07 19:29:20] ❌ Error extracting company name: 'NoneType' object is not subscriptable
[2025-07-07 19:29:20] Tally connected. Fetching data...
[2025-07-07 19:29:20] Sending data request to http://localhost:9000 with XML: 
    <ENVELOPE>
        <HEADER>
            <TALLYREQUEST>Export Data</TALLYREQUEST>
        </HEAD
[2025-07-07 19:29:24] ✅ API connector session closed
[2025-07-07 20:17:58] Loaded TALLY_URL: http://localhost:9000
[2025-07-07 20:18:01] Sync Data button clicked.
[2025-07-07 20:18:01] Sending test connection POST to http://localhost:9000
[2025-07-07 20:18:26] Test connection response: status=200, text=<ENVELOPE>

 <HEADER>

  <TALLYREQUEST>Import Data</TALLYREQUEST>

 </HEADER>

 <BODY>

  <IMPORTDATA>

   <REQUESTDESC>

    <REPORTNAME>All Masters</REPORTNAME>

    <STATICVARIABLES>

     <SVCURRE
[2025-07-07 20:18:26] Sending data request to http://localhost:9000 with XML: 
    <ENVELOPE>
        <HEADER>
            <TALLYREQUEST>Export Data</TALLYREQUEST>
        </HEAD
[2025-07-07 20:19:58] ❌ Error fetching data from Tally: ('Connection aborted.', ConnectionResetError(10054, 'An existing connection was forcibly closed by the remote host', None, 10054, None))
[2025-07-07 20:20:06] ❌ Error extracting company name: 'NoneType' object is not subscriptable
[2025-07-07 20:20:06] Tally connected. Fetching data...
[2025-07-07 20:20:06] Sending data request to http://localhost:9000 with XML: 
    <ENVELOPE>
        <HEADER>
            <TALLYREQUEST>Export Data</TALLYREQUEST>
        </HEAD
[2025-07-07 20:20:11] ❌ Error fetching data from Tally: HTTPConnectionPool(host='localhost', port=9000): Max retries exceeded with url: / (Caused by NewConnectionError('<urllib3.connection.HTTPConnection object at 0x00000226BDA95BD0>: Failed to establish a new connection: [WinError 10061] No connection could be made because the target machine actively refused it'))
[2025-07-07 20:20:13] No data fetched from Tally.
[2025-07-07 20:23:44] ✅ API connector session closed
[2025-07-07 20:23:45] Loaded TALLY_URL: http://localhost:9000
[2025-07-07 20:23:48] Sync Data button clicked.
[2025-07-07 20:23:48] Sending test connection POST to http://localhost:9000
[2025-07-07 20:23:51] Test connection response: status=200, text=<RESPONSE>Unknown Request, cannot be processed</RESPONSE>


[2025-07-07 20:23:51] ❌ Invalid response from Tally: <RESPONSE>Unknown Request, cannot be processed</RESPONSE>


[2025-07-07 20:23:57] Tally not connected. Sync aborted.
[2025-07-07 20:26:22] ✅ API connector session closed
[2025-07-07 20:26:24] Loaded TALLY_URL: http://localhost:9000
[2025-07-07 20:26:25] Sync Data button clicked.
[2025-07-07 20:26:25] Sending test connection POST to http://localhost:9000
[2025-07-07 20:26:27] Test connection response: status=200, text=<RESPONSE>Unknown Request, cannot be processed</RESPONSE>


[2025-07-07 20:26:27] ❌ Invalid response from Tally: <RESPONSE>Unknown Request, cannot be processed</RESPONSE>


[2025-07-07 20:26:29] Tally not connected. Sync aborted.
[2025-07-07 20:28:07] ✅ API connector session closed
[2025-07-07 20:28:09] Loaded TALLY_URL: http://localhost:9000
[2025-07-07 20:28:15] Sync Data button clicked.
[2025-07-07 20:28:15] Sending test connection POST to http://localhost:9000
[2025-07-07 20:28:17] Test connection response: status=200, text=<ENVELOPE>

 <HEADER>

  <TALLYREQUEST>Import Data</TALLYREQUEST>

 </HEADER>

 <BODY>

  <IMPORTDATA>

   <REQUESTDESC>

    <REPORTNAME>All Masters</REPORTNAME>

    <STATICVARIABLES>

     <SVCURRE
[2025-07-07 20:28:17] Sending data request to http://localhost:9000 with XML: 
    <ENVELOPE>
        <HEADER>
            <TALLYREQUEST>Export Data</TALLYREQUEST>
        </HEAD
[2025-07-07 20:30:26] ❌ Timeout while connecting to Tally.
[2025-07-07 20:30:39] ❌ Error extracting company name: 'NoneType' object is not subscriptable
[2025-07-07 20:30:39] Tally connected. Fetching data...
[2025-07-07 20:30:39] Sending data request to http://localhost:9000 with XML: 
    <ENVELOPE>
        <HEADER>
            <TALLYREQUEST>Export Data</TALLYREQUEST>
        </HEAD
[2025-07-07 20:32:41] ❌ Timeout while connecting to Tally.
[2025-07-07 20:36:14] No data fetched from Tally.
[2025-07-07 21:33:18] Sync Data button clicked.
[2025-07-07 21:33:18] Sending test connection POST to http://localhost:9000
[2025-07-07 21:33:19] Test connection response: status=200, text=<ENVELOPE>

 <HEADER>

  <TALLYREQUEST>Import Data</TALLYREQUEST>

 </HEADER>

 <BODY>

  <IMPORTDATA>

   <REQUESTDESC>

    <REPORTNAME>All Masters</REPORTNAME>

    <STATICVARIABLES>

     <SVCURRE
[2025-07-07 21:33:19] Sending data request to http://localhost:9000 with XML: 
    <ENVELOPE>
        <HEADER>
            <TALLYREQUEST>Export Data</TALLYREQUEST>
        </HEAD
[2025-07-07 21:35:31] ❌ Timeout while connecting to Tally.

