[2025-07-04 16:23:27] Loaded TALLY_URL: None
[2025-07-04 16:23:30] Sync Data button clicked.
[2025-07-04 16:23:30] Sending test connection POST to None
[2025-07-04 16:23:30] ❌ Connection failed: Invalid URL 'None': No scheme supplied. Perhaps you meant https://None?
Traceback (most recent call last):
  File "C:\Users\Admin\Nilesh_Projects\CFA\cfa_ai_app\Desktop_tally_sync-agent\tally_connector.py", line 52, in test_tally_connection
    response = requests.post(TALLY_URL, data=test_request, timeout=20)
  File "C:\Users\Admin\Nilesh_Projects\CFA\cfa_ai_app\backend\venv\Lib\site-packages\requests\api.py", line 115, in post
    return request("post", url, data=data, json=json, **kwargs)
  File "C:\Users\Admin\Nilesh_Projects\CFA\cfa_ai_app\backend\venv\Lib\site-packages\requests\api.py", line 59, in request
    return session.request(method=method, url=url, **kwargs)
           ~~~~~~~~~~~~~~~^^^^^^^^^^^^^^^^^^^^^^^^^^^^^^^^^^
  File "C:\Users\Admin\Nilesh_Projects\CFA\cfa_ai_app\backend\venv\Lib\site-packages\requests\sessions.py", line 575, in request
    prep = self.prepare_request(req)
  File "C:\Users\Admin\Nilesh_Projects\CFA\cfa_ai_app\backend\venv\Lib\site-packages\requests\sessions.py", line 484, in prepare_request
    p.prepare(
    ~~~~~~~~~^
        method=request.method.upper(),
        ^^^^^^^^^^^^^^^^^^^^^^^^^^^^^^
    ...<10 lines>...
        hooks=merge_hooks(request.hooks, self.hooks),
        ^^^^^^^^^^^^^^^^^^^^^^^^^^^^^^^^^^^^^^^^^^^^^
    )
    ^
  File "C:\Users\Admin\Nilesh_Projects\CFA\cfa_ai_app\backend\venv\Lib\site-packages\requests\models.py", line 367, in prepare
    self.prepare_url(url, params)
    ~~~~~~~~~~~~~~~~^^^^^^^^^^^^^
  File "C:\Users\Admin\Nilesh_Projects\CFA\cfa_ai_app\backend\venv\Lib\site-packages\requests\models.py", line 438, in prepare_url
    raise MissingSchema(
    ...<2 lines>...
    )
requests.exceptions.MissingSchema: Invalid URL 'None': No scheme supplied. Perhaps you meant https://None?

[2025-07-04 16:23:34] Tally not connected. Sync aborted.
[2025-07-05 15:42:17] Loaded TALLY_URL: localhost:9000
[2025-07-05 15:42:22] Sync Data button clicked.
[2025-07-05 15:42:22] Sending test connection POST to localhost:9000
[2025-07-05 15:42:24] ❌ Connection failed: No connection adapters were found for 'localhost:9000'
Traceback (most recent call last):
  File "C:\Users\Admin\Nilesh_Projects\CFA\cfa_ai_app\Desktop_tally_sync-agent\tally_connector.py", line 54, in test_tally_connection
    response = requests.post(TALLY_URL, data=test_request, timeout=150)  # 2 minutes
  File "C:\Users\Admin\Nilesh_Projects\CFA\cfa_ai_app\backend\venv\Lib\site-packages\requests\api.py", line 115, in post
    return request("post", url, data=data, json=json, **kwargs)
  File "C:\Users\Admin\Nilesh_Projects\CFA\cfa_ai_app\backend\venv\Lib\site-packages\requests\api.py", line 59, in request
    return session.request(method=method, url=url, **kwargs)
           ~~~~~~~~~~~~~~~^^^^^^^^^^^^^^^^^^^^^^^^^^^^^^^^^^
  File "C:\Users\Admin\Nilesh_Projects\CFA\cfa_ai_app\backend\venv\Lib\site-packages\requests\sessions.py", line 589, in request
    resp = self.send(prep, **send_kwargs)
  File "C:\Users\Admin\Nilesh_Projects\CFA\cfa_ai_app\backend\venv\Lib\site-packages\requests\sessions.py", line 697, in send
    adapter = self.get_adapter(url=request.url)
  File "C:\Users\Admin\Nilesh_Projects\CFA\cfa_ai_app\backend\venv\Lib\site-packages\requests\sessions.py", line 792, in get_adapter
    raise InvalidSchema(f"No connection adapters were found for {url!r}")
requests.exceptions.InvalidSchema: No connection adapters were found for 'localhost:9000'

[2025-07-05 15:42:26] Tally not connected. Sync aborted.
[2025-07-05 16:16:18] Loaded TALLY_URL: localhost:9000
[2025-07-05 16:16:31] Sync Data button clicked.
[2025-07-05 16:16:31] Sending test connection POST to localhost:9000
[2025-07-05 16:16:34] ❌ Connection failed: No connection adapters were found for 'localhost:9000'
Traceback (most recent call last):
  File "C:\Users\Admin\Nilesh_Projects\CFA\cfa_ai_app\Desktop_tally_sync-agent\tally_connector.py", line 54, in test_tally_connection
    response = requests.post(TALLY_URL, data=test_request, timeout=150)  # 2 minutes
  File "C:\Users\Admin\Nilesh_Projects\CFA\cfa_ai_app\backend\venv\Lib\site-packages\requests\api.py", line 115, in post
    return request("post", url, data=data, json=json, **kwargs)
  File "C:\Users\Admin\Nilesh_Projects\CFA\cfa_ai_app\backend\venv\Lib\site-packages\requests\api.py", line 59, in request
    return session.request(method=method, url=url, **kwargs)
           ~~~~~~~~~~~~~~~^^^^^^^^^^^^^^^^^^^^^^^^^^^^^^^^^^
  File "C:\Users\Admin\Nilesh_Projects\CFA\cfa_ai_app\backend\venv\Lib\site-packages\requests\sessions.py", line 589, in request
    resp = self.send(prep, **send_kwargs)
  File "C:\Users\Admin\Nilesh_Projects\CFA\cfa_ai_app\backend\venv\Lib\site-packages\requests\sessions.py", line 697, in send
    adapter = self.get_adapter(url=request.url)
  File "C:\Users\Admin\Nilesh_Projects\CFA\cfa_ai_app\backend\venv\Lib\site-packages\requests\sessions.py", line 792, in get_adapter
    raise InvalidSchema(f"No connection adapters were found for {url!r}")
requests.exceptions.InvalidSchema: No connection adapters were found for 'localhost:9000'

[2025-07-05 16:16:35] Tally not connected. Sync aborted.
[2025-07-05 16:17:55] Sync Data button clicked.
[2025-07-05 16:17:55] Sending test connection POST to localhost:9000
[2025-07-05 16:17:57] ❌ Connection failed: No connection adapters were found for 'localhost:9000'
Traceback (most recent call last):
  File "C:\Users\Admin\Nilesh_Projects\CFA\cfa_ai_app\Desktop_tally_sync-agent\tally_connector.py", line 54, in test_tally_connection
    response = requests.post(TALLY_URL, data=test_request, timeout=150)  # 2 minutes
  File "C:\Users\Admin\Nilesh_Projects\CFA\cfa_ai_app\backend\venv\Lib\site-packages\requests\api.py", line 115, in post
    return request("post", url, data=data, json=json, **kwargs)
  File "C:\Users\Admin\Nilesh_Projects\CFA\cfa_ai_app\backend\venv\Lib\site-packages\requests\api.py", line 59, in request
    return session.request(method=method, url=url, **kwargs)
           ~~~~~~~~~~~~~~~^^^^^^^^^^^^^^^^^^^^^^^^^^^^^^^^^^
  File "C:\Users\Admin\Nilesh_Projects\CFA\cfa_ai_app\backend\venv\Lib\site-packages\requests\sessions.py", line 589, in request
    resp = self.send(prep, **send_kwargs)
  File "C:\Users\Admin\Nilesh_Projects\CFA\cfa_ai_app\backend\venv\Lib\site-packages\requests\sessions.py", line 697, in send
    adapter = self.get_adapter(url=request.url)
  File "C:\Users\Admin\Nilesh_Projects\CFA\cfa_ai_app\backend\venv\Lib\site-packages\requests\sessions.py", line 792, in get_adapter
    raise InvalidSchema(f"No connection adapters were found for {url!r}")
requests.exceptions.InvalidSchema: No connection adapters were found for 'localhost:9000'

[2025-07-05 16:17:58] Tally not connected. Sync aborted.
[2025-07-05 16:19:52] Loaded TALLY_URL: http://localhost:9000
[2025-07-05 16:19:54] Sync Data button clicked.
[2025-07-05 16:19:54] Sending test connection POST to http://localhost:9000
[2025-07-05 16:20:03] ❌ Connection failed: ('Connection aborted.', ConnectionResetError(10054, 'An existing connection was forcibly closed by the remote host', None, 10054, None))
Traceback (most recent call last):
  File "C:\Users\Admin\Nilesh_Projects\CFA\cfa_ai_app\backend\venv\Lib\site-packages\urllib3\connectionpool.py", line 787, in urlopen
    response = self._make_request(
        conn,
    ...<10 lines>...
        **response_kw,
    )
  File "C:\Users\Admin\Nilesh_Projects\CFA\cfa_ai_app\backend\venv\Lib\site-packages\urllib3\connectionpool.py", line 534, in _make_request
    response = conn.getresponse()
  File "C:\Users\Admin\Nilesh_Projects\CFA\cfa_ai_app\backend\venv\Lib\site-packages\urllib3\connection.py", line 565, in getresponse
    httplib_response = super().getresponse()
  File "C:\Users\Admin\AppData\Local\Programs\Python\Python313\Lib\http\client.py", line 1430, in getresponse
    response.begin()
    ~~~~~~~~~~~~~~^^
  File "C:\Users\Admin\AppData\Local\Programs\Python\Python313\Lib\http\client.py", line 331, in begin
    version, status, reason = self._read_status()
                              ~~~~~~~~~~~~~~~~~^^
  File "C:\Users\Admin\AppData\Local\Programs\Python\Python313\Lib\http\client.py", line 292, in _read_status
    line = str(self.fp.readline(_MAXLINE + 1), "iso-8859-1")
               ~~~~~~~~~~~~~~~~^^^^^^^^^^^^^^
  File "C:\Users\Admin\AppData\Local\Programs\Python\Python313\Lib\socket.py", line 719, in readinto
    return self._sock.recv_into(b)
           ~~~~~~~~~~~~~~~~~~~~^^^
ConnectionResetError: [WinError 10054] An existing connection was forcibly closed by the remote host

During handling of the above exception, another exception occurred:

Traceback (most recent call last):
  File "C:\Users\Admin\Nilesh_Projects\CFA\cfa_ai_app\backend\venv\Lib\site-packages\requests\adapters.py", line 667, in send
    resp = conn.urlopen(
        method=request.method,
    ...<9 lines>...
        chunked=chunked,
    )
  File "C:\Users\Admin\Nilesh_Projects\CFA\cfa_ai_app\backend\venv\Lib\site-packages\urllib3\connectionpool.py", line 841, in urlopen
    retries = retries.increment(
        method, url, error=new_e, _pool=self, _stacktrace=sys.exc_info()[2]
    )
  File "C:\Users\Admin\Nilesh_Projects\CFA\cfa_ai_app\backend\venv\Lib\site-packages\urllib3\util\retry.py", line 474, in increment
    raise reraise(type(error), error, _stacktrace)
          ~~~~~~~^^^^^^^^^^^^^^^^^^^^^^^^^^^^^^^^^
  File "C:\Users\Admin\Nilesh_Projects\CFA\cfa_ai_app\backend\venv\Lib\site-packages\urllib3\util\util.py", line 38, in reraise
    raise value.with_traceback(tb)
  File "C:\Users\Admin\Nilesh_Projects\CFA\cfa_ai_app\backend\venv\Lib\site-packages\urllib3\connectionpool.py", line 787, in urlopen
    response = self._make_request(
        conn,
    ...<10 lines>...
        **response_kw,
    )
  File "C:\Users\Admin\Nilesh_Projects\CFA\cfa_ai_app\backend\venv\Lib\site-packages\urllib3\connectionpool.py", line 534, in _make_request
    response = conn.getresponse()
  File "C:\Users\Admin\Nilesh_Projects\CFA\cfa_ai_app\backend\venv\Lib\site-packages\urllib3\connection.py", line 565, in getresponse
    httplib_response = super().getresponse()
  File "C:\Users\Admin\AppData\Local\Programs\Python\Python313\Lib\http\client.py", line 1430, in getresponse
    response.begin()
    ~~~~~~~~~~~~~~^^
  File "C:\Users\Admin\AppData\Local\Programs\Python\Python313\Lib\http\client.py", line 331, in begin
    version, status, reason = self._read_status()
                              ~~~~~~~~~~~~~~~~~^^
  File "C:\Users\Admin\AppData\Local\Programs\Python\Python313\Lib\http\client.py", line 292, in _read_status
    line = str(self.fp.readline(_MAXLINE + 1), "iso-8859-1")
               ~~~~~~~~~~~~~~~~^^^^^^^^^^^^^^
  File "C:\Users\Admin\AppData\Local\Programs\Python\Python313\Lib\socket.py", line 719, in readinto
    return self._sock.recv_into(b)
           ~~~~~~~~~~~~~~~~~~~~^^^
urllib3.exceptions.ProtocolError: ('Connection aborted.', ConnectionResetError(10054, 'An existing connection was forcibly closed by the remote host', None, 10054, None))

During handling of the above exception, another exception occurred:

Traceback (most recent call last):
  File "C:\Users\Admin\Nilesh_Projects\CFA\cfa_ai_app\Desktop_tally_sync-agent\tally_connector.py", line 54, in test_tally_connection
    response = requests.post(TALLY_URL, data=test_request, timeout=150)  # 2 minutes
  File "C:\Users\Admin\Nilesh_Projects\CFA\cfa_ai_app\backend\venv\Lib\site-packages\requests\api.py", line 115, in post
    return request("post", url, data=data, json=json, **kwargs)
  File "C:\Users\Admin\Nilesh_Projects\CFA\cfa_ai_app\backend\venv\Lib\site-packages\requests\api.py", line 59, in request
    return session.request(method=method, url=url, **kwargs)
           ~~~~~~~~~~~~~~~^^^^^^^^^^^^^^^^^^^^^^^^^^^^^^^^^^
  File "C:\Users\Admin\Nilesh_Projects\CFA\cfa_ai_app\backend\venv\Lib\site-packages\requests\sessions.py", line 589, in request
    resp = self.send(prep, **send_kwargs)
  File "C:\Users\Admin\Nilesh_Projects\CFA\cfa_ai_app\backend\venv\Lib\site-packages\requests\sessions.py", line 703, in send
    r = adapter.send(request, **kwargs)
  File "C:\Users\Admin\Nilesh_Projects\CFA\cfa_ai_app\backend\venv\Lib\site-packages\requests\adapters.py", line 682, in send
    raise ConnectionError(err, request=request)
requests.exceptions.ConnectionError: ('Connection aborted.', ConnectionResetError(10054, 'An existing connection was forcibly closed by the remote host', None, 10054, None))

[2025-07-05 16:20:05] Tally not connected. Sync aborted.
[2025-07-05 16:23:16] Loaded TALLY_URL: http://localhost:9000
[2025-07-05 16:23:19] Sync Data button clicked.
[2025-07-05 16:23:19] Sending test connection POST to http://localhost:9000
[2025-07-05 16:23:24] ❌ Connection failed: HTTPConnectionPool(host='localhost', port=9000): Max retries exceeded with url: / (Caused by NewConnectionError('<urllib3.connection.HTTPConnection object at 0x00000223CB4F4D70>: Failed to establish a new connection: [WinError 10061] No connection could be made because the target machine actively refused it'))
Traceback (most recent call last):
  File "C:\Users\Admin\Nilesh_Projects\CFA\cfa_ai_app\backend\venv\Lib\site-packages\urllib3\connection.py", line 198, in _new_conn
    sock = connection.create_connection(
        (self._dns_host, self.port),
    ...<2 lines>...
        socket_options=self.socket_options,
    )
  File "C:\Users\Admin\Nilesh_Projects\CFA\cfa_ai_app\backend\venv\Lib\site-packages\urllib3\util\connection.py", line 85, in create_connection
    raise err
  File "C:\Users\Admin\Nilesh_Projects\CFA\cfa_ai_app\backend\venv\Lib\site-packages\urllib3\util\connection.py", line 73, in create_connection
    sock.connect(sa)
    ~~~~~~~~~~~~^^^^
ConnectionRefusedError: [WinError 10061] No connection could be made because the target machine actively refused it

The above exception was the direct cause of the following exception:

Traceback (most recent call last):
  File "C:\Users\Admin\Nilesh_Projects\CFA\cfa_ai_app\backend\venv\Lib\site-packages\urllib3\connectionpool.py", line 787, in urlopen
    response = self._make_request(
        conn,
    ...<10 lines>...
        **response_kw,
    )
  File "C:\Users\Admin\Nilesh_Projects\CFA\cfa_ai_app\backend\venv\Lib\site-packages\urllib3\connectionpool.py", line 493, in _make_request
    conn.request(
    ~~~~~~~~~~~~^
        method,
        ^^^^^^^
    ...<6 lines>...
        enforce_content_length=enforce_content_length,
        ^^^^^^^^^^^^^^^^^^^^^^^^^^^^^^^^^^^^^^^^^^^^^^
    )
    ^
  File "C:\Users\Admin\Nilesh_Projects\CFA\cfa_ai_app\backend\venv\Lib\site-packages\urllib3\connection.py", line 494, in request
    self.endheaders()
    ~~~~~~~~~~~~~~~^^
  File "C:\Users\Admin\AppData\Local\Programs\Python\Python313\Lib\http\client.py", line 1333, in endheaders
    self._send_output(message_body, encode_chunked=encode_chunked)
    ~~~~~~~~~~~~~~~~~^^^^^^^^^^^^^^^^^^^^^^^^^^^^^^^^^^^^^^^^^^^^^
  File "C:\Users\Admin\AppData\Local\Programs\Python\Python313\Lib\http\client.py", line 1093, in _send_output
    self.send(msg)
    ~~~~~~~~~^^^^^
  File "C:\Users\Admin\AppData\Local\Programs\Python\Python313\Lib\http\client.py", line 1037, in send
    self.connect()
    ~~~~~~~~~~~~^^
  File "C:\Users\Admin\Nilesh_Projects\CFA\cfa_ai_app\backend\venv\Lib\site-packages\urllib3\connection.py", line 325, in connect
    self.sock = self._new_conn()
                ~~~~~~~~~~~~~~^^
  File "C:\Users\Admin\Nilesh_Projects\CFA\cfa_ai_app\backend\venv\Lib\site-packages\urllib3\connection.py", line 213, in _new_conn
    raise NewConnectionError(
        self, f"Failed to establish a new connection: {e}"
    ) from e
urllib3.exceptions.NewConnectionError: <urllib3.connection.HTTPConnection object at 0x00000223CB4F4D70>: Failed to establish a new connection: [WinError 10061] No connection could be made because the target machine actively refused it

The above exception was the direct cause of the following exception:

Traceback (most recent call last):
  File "C:\Users\Admin\Nilesh_Projects\CFA\cfa_ai_app\backend\venv\Lib\site-packages\requests\adapters.py", line 667, in send
    resp = conn.urlopen(
        method=request.method,
    ...<9 lines>...
        chunked=chunked,
    )
  File "C:\Users\Admin\Nilesh_Projects\CFA\cfa_ai_app\backend\venv\Lib\site-packages\urllib3\connectionpool.py", line 841, in urlopen
    retries = retries.increment(
        method, url, error=new_e, _pool=self, _stacktrace=sys.exc_info()[2]
    )
  File "C:\Users\Admin\Nilesh_Projects\CFA\cfa_ai_app\backend\venv\Lib\site-packages\urllib3\util\retry.py", line 519, in increment
    raise MaxRetryError(_pool, url, reason) from reason  # type: ignore[arg-type]
    ^^^^^^^^^^^^^^^^^^^^^^^^^^^^^^^^^^^^^^^^^^^^^^^^^^^
urllib3.exceptions.MaxRetryError: HTTPConnectionPool(host='localhost', port=9000): Max retries exceeded with url: / (Caused by NewConnectionError('<urllib3.connection.HTTPConnection object at 0x00000223CB4F4D70>: Failed to establish a new connection: [WinError 10061] No connection could be made because the target machine actively refused it'))

During handling of the above exception, another exception occurred:

Traceback (most recent call last):
  File "C:\Users\Admin\Nilesh_Projects\CFA\cfa_ai_app\Desktop_tally_sync-agent\tally_connector.py", line 50, in test_tally_connection
    response = requests.post(TALLY_URL, data=test_request, timeout=150)  # 2 minutes
  File "C:\Users\Admin\Nilesh_Projects\CFA\cfa_ai_app\backend\venv\Lib\site-packages\requests\api.py", line 115, in post
    return request("post", url, data=data, json=json, **kwargs)
  File "C:\Users\Admin\Nilesh_Projects\CFA\cfa_ai_app\backend\venv\Lib\site-packages\requests\api.py", line 59, in request
    return session.request(method=method, url=url, **kwargs)
           ~~~~~~~~~~~~~~~^^^^^^^^^^^^^^^^^^^^^^^^^^^^^^^^^^
  File "C:\Users\Admin\Nilesh_Projects\CFA\cfa_ai_app\backend\venv\Lib\site-packages\requests\sessions.py", line 589, in request
    resp = self.send(prep, **send_kwargs)
  File "C:\Users\Admin\Nilesh_Projects\CFA\cfa_ai_app\backend\venv\Lib\site-packages\requests\sessions.py", line 703, in send
    r = adapter.send(request, **kwargs)
  File "C:\Users\Admin\Nilesh_Projects\CFA\cfa_ai_app\backend\venv\Lib\site-packages\requests\adapters.py", line 700, in send
    raise ConnectionError(e, request=request)
requests.exceptions.ConnectionError: HTTPConnectionPool(host='localhost', port=9000): Max retries exceeded with url: / (Caused by NewConnectionError('<urllib3.connection.HTTPConnection object at 0x00000223CB4F4D70>: Failed to establish a new connection: [WinError 10061] No connection could be made because the target machine actively refused it'))

[2025-07-05 16:23:29] Tally not connected. Sync aborted.
[2025-07-05 16:25:38] Sync Data button clicked.
[2025-07-05 16:25:38] Sending test connection POST to http://localhost:9000
[2025-07-05 16:26:17] ❌ Connection failed: ('Connection aborted.', ConnectionResetError(10054, 'An existing connection was forcibly closed by the remote host', None, 10054, None))
Traceback (most recent call last):
  File "C:\Users\Admin\Nilesh_Projects\CFA\cfa_ai_app\backend\venv\Lib\site-packages\urllib3\connectionpool.py", line 787, in urlopen
    response = self._make_request(
        conn,
    ...<10 lines>...
        **response_kw,
    )
  File "C:\Users\Admin\Nilesh_Projects\CFA\cfa_ai_app\backend\venv\Lib\site-packages\urllib3\connectionpool.py", line 534, in _make_request
    response = conn.getresponse()
  File "C:\Users\Admin\Nilesh_Projects\CFA\cfa_ai_app\backend\venv\Lib\site-packages\urllib3\connection.py", line 565, in getresponse
    httplib_response = super().getresponse()
  File "C:\Users\Admin\AppData\Local\Programs\Python\Python313\Lib\http\client.py", line 1430, in getresponse
    response.begin()
    ~~~~~~~~~~~~~~^^
  File "C:\Users\Admin\AppData\Local\Programs\Python\Python313\Lib\http\client.py", line 331, in begin
    version, status, reason = self._read_status()
                              ~~~~~~~~~~~~~~~~~^^
  File "C:\Users\Admin\AppData\Local\Programs\Python\Python313\Lib\http\client.py", line 292, in _read_status
    line = str(self.fp.readline(_MAXLINE + 1), "iso-8859-1")
               ~~~~~~~~~~~~~~~~^^^^^^^^^^^^^^
  File "C:\Users\Admin\AppData\Local\Programs\Python\Python313\Lib\socket.py", line 719, in readinto
    return self._sock.recv_into(b)
           ~~~~~~~~~~~~~~~~~~~~^^^
ConnectionResetError: [WinError 10054] An existing connection was forcibly closed by the remote host

During handling of the above exception, another exception occurred:

Traceback (most recent call last):
  File "C:\Users\Admin\Nilesh_Projects\CFA\cfa_ai_app\backend\venv\Lib\site-packages\requests\adapters.py", line 667, in send
    resp = conn.urlopen(
        method=request.method,
    ...<9 lines>...
        chunked=chunked,
    )
  File "C:\Users\Admin\Nilesh_Projects\CFA\cfa_ai_app\backend\venv\Lib\site-packages\urllib3\connectionpool.py", line 841, in urlopen
    retries = retries.increment(
        method, url, error=new_e, _pool=self, _stacktrace=sys.exc_info()[2]
    )
  File "C:\Users\Admin\Nilesh_Projects\CFA\cfa_ai_app\backend\venv\Lib\site-packages\urllib3\util\retry.py", line 474, in increment
    raise reraise(type(error), error, _stacktrace)
          ~~~~~~~^^^^^^^^^^^^^^^^^^^^^^^^^^^^^^^^^
  File "C:\Users\Admin\Nilesh_Projects\CFA\cfa_ai_app\backend\venv\Lib\site-packages\urllib3\util\util.py", line 38, in reraise
    raise value.with_traceback(tb)
  File "C:\Users\Admin\Nilesh_Projects\CFA\cfa_ai_app\backend\venv\Lib\site-packages\urllib3\connectionpool.py", line 787, in urlopen
    response = self._make_request(
        conn,
    ...<10 lines>...
        **response_kw,
    )
  File "C:\Users\Admin\Nilesh_Projects\CFA\cfa_ai_app\backend\venv\Lib\site-packages\urllib3\connectionpool.py", line 534, in _make_request
    response = conn.getresponse()
  File "C:\Users\Admin\Nilesh_Projects\CFA\cfa_ai_app\backend\venv\Lib\site-packages\urllib3\connection.py", line 565, in getresponse
    httplib_response = super().getresponse()
  File "C:\Users\Admin\AppData\Local\Programs\Python\Python313\Lib\http\client.py", line 1430, in getresponse
    response.begin()
    ~~~~~~~~~~~~~~^^
  File "C:\Users\Admin\AppData\Local\Programs\Python\Python313\Lib\http\client.py", line 331, in begin
    version, status, reason = self._read_status()
                              ~~~~~~~~~~~~~~~~~^^
  File "C:\Users\Admin\AppData\Local\Programs\Python\Python313\Lib\http\client.py", line 292, in _read_status
    line = str(self.fp.readline(_MAXLINE + 1), "iso-8859-1")
               ~~~~~~~~~~~~~~~~^^^^^^^^^^^^^^
  File "C:\Users\Admin\AppData\Local\Programs\Python\Python313\Lib\socket.py", line 719, in readinto
    return self._sock.recv_into(b)
           ~~~~~~~~~~~~~~~~~~~~^^^
urllib3.exceptions.ProtocolError: ('Connection aborted.', ConnectionResetError(10054, 'An existing connection was forcibly closed by the remote host', None, 10054, None))

During handling of the above exception, another exception occurred:

Traceback (most recent call last):
  File "C:\Users\Admin\Nilesh_Projects\CFA\cfa_ai_app\Desktop_tally_sync-agent\tally_connector.py", line 50, in test_tally_connection
    response = requests.post(TALLY_URL, data=test_request, timeout=150)  # 2 minutes
  File "C:\Users\Admin\Nilesh_Projects\CFA\cfa_ai_app\backend\venv\Lib\site-packages\requests\api.py", line 115, in post
    return request("post", url, data=data, json=json, **kwargs)
  File "C:\Users\Admin\Nilesh_Projects\CFA\cfa_ai_app\backend\venv\Lib\site-packages\requests\api.py", line 59, in request
    return session.request(method=method, url=url, **kwargs)
           ~~~~~~~~~~~~~~~^^^^^^^^^^^^^^^^^^^^^^^^^^^^^^^^^^
  File "C:\Users\Admin\Nilesh_Projects\CFA\cfa_ai_app\backend\venv\Lib\site-packages\requests\sessions.py", line 589, in request
    resp = self.send(prep, **send_kwargs)
  File "C:\Users\Admin\Nilesh_Projects\CFA\cfa_ai_app\backend\venv\Lib\site-packages\requests\sessions.py", line 703, in send
    r = adapter.send(request, **kwargs)
  File "C:\Users\Admin\Nilesh_Projects\CFA\cfa_ai_app\backend\venv\Lib\site-packages\requests\adapters.py", line 682, in send
    raise ConnectionError(err, request=request)
requests.exceptions.ConnectionError: ('Connection aborted.', ConnectionResetError(10054, 'An existing connection was forcibly closed by the remote host', None, 10054, None))

[2025-07-05 16:26:18] Tally not connected. Sync aborted.
[2025-07-05 16:43:20] Loaded TALLY_URL: http://localhost:9000
[2025-07-05 16:44:03] Sync Data button clicked.
[2025-07-05 16:44:03] Sending test connection POST to http://localhost:9000
[2025-07-05 16:46:34] ❌ Connection failed: HTTPConnectionPool(host='localhost', port=9000): Read timed out. (read timeout=150)
Traceback (most recent call last):
  File "C:\Users\Admin\Nilesh_Projects\CFA\cfa_ai_app\backend\venv\Lib\site-packages\urllib3\connectionpool.py", line 534, in _make_request
    response = conn.getresponse()
  File "C:\Users\Admin\Nilesh_Projects\CFA\cfa_ai_app\backend\venv\Lib\site-packages\urllib3\connection.py", line 565, in getresponse
    httplib_response = super().getresponse()
  File "C:\Users\Admin\AppData\Local\Programs\Python\Python313\Lib\http\client.py", line 1430, in getresponse
    response.begin()
    ~~~~~~~~~~~~~~^^
  File "C:\Users\Admin\AppData\Local\Programs\Python\Python313\Lib\http\client.py", line 331, in begin
    version, status, reason = self._read_status()
                              ~~~~~~~~~~~~~~~~~^^
  File "C:\Users\Admin\AppData\Local\Programs\Python\Python313\Lib\http\client.py", line 292, in _read_status
    line = str(self.fp.readline(_MAXLINE + 1), "iso-8859-1")
               ~~~~~~~~~~~~~~~~^^^^^^^^^^^^^^
  File "C:\Users\Admin\AppData\Local\Programs\Python\Python313\Lib\socket.py", line 719, in readinto
    return self._sock.recv_into(b)
           ~~~~~~~~~~~~~~~~~~~~^^^
TimeoutError: timed out

The above exception was the direct cause of the following exception:

Traceback (most recent call last):
  File "C:\Users\Admin\Nilesh_Projects\CFA\cfa_ai_app\backend\venv\Lib\site-packages\requests\adapters.py", line 667, in send
    resp = conn.urlopen(
        method=request.method,
    ...<9 lines>...
        chunked=chunked,
    )
  File "C:\Users\Admin\Nilesh_Projects\CFA\cfa_ai_app\backend\venv\Lib\site-packages\urllib3\connectionpool.py", line 841, in urlopen
    retries = retries.increment(
        method, url, error=new_e, _pool=self, _stacktrace=sys.exc_info()[2]
    )
  File "C:\Users\Admin\Nilesh_Projects\CFA\cfa_ai_app\backend\venv\Lib\site-packages\urllib3\util\retry.py", line 474, in increment
    raise reraise(type(error), error, _stacktrace)
          ~~~~~~~^^^^^^^^^^^^^^^^^^^^^^^^^^^^^^^^^
  File "C:\Users\Admin\Nilesh_Projects\CFA\cfa_ai_app\backend\venv\Lib\site-packages\urllib3\util\util.py", line 39, in reraise
    raise value
  File "C:\Users\Admin\Nilesh_Projects\CFA\cfa_ai_app\backend\venv\Lib\site-packages\urllib3\connectionpool.py", line 787, in urlopen
    response = self._make_request(
        conn,
    ...<10 lines>...
        **response_kw,
    )
  File "C:\Users\Admin\Nilesh_Projects\CFA\cfa_ai_app\backend\venv\Lib\site-packages\urllib3\connectionpool.py", line 536, in _make_request
    self._raise_timeout(err=e, url=url, timeout_value=read_timeout)
    ~~~~~~~~~~~~~~~~~~~^^^^^^^^^^^^^^^^^^^^^^^^^^^^^^^^^^^^^^^^^^^^
  File "C:\Users\Admin\Nilesh_Projects\CFA\cfa_ai_app\backend\venv\Lib\site-packages\urllib3\connectionpool.py", line 367, in _raise_timeout
    raise ReadTimeoutError(
        self, url, f"Read timed out. (read timeout={timeout_value})"
    ) from err
urllib3.exceptions.ReadTimeoutError: HTTPConnectionPool(host='localhost', port=9000): Read timed out. (read timeout=150)

During handling of the above exception, another exception occurred:

Traceback (most recent call last):
  File "C:\Users\Admin\Nilesh_Projects\CFA\cfa_ai_app\Desktop_tally_sync-agent\tally_connector.py", line 50, in test_tally_connection
    response = requests.post(TALLY_URL, data=test_request, timeout=150)  # 2 minutes
  File "C:\Users\Admin\Nilesh_Projects\CFA\cfa_ai_app\backend\venv\Lib\site-packages\requests\api.py", line 115, in post
    return request("post", url, data=data, json=json, **kwargs)
  File "C:\Users\Admin\Nilesh_Projects\CFA\cfa_ai_app\backend\venv\Lib\site-packages\requests\api.py", line 59, in request
    return session.request(method=method, url=url, **kwargs)
           ~~~~~~~~~~~~~~~^^^^^^^^^^^^^^^^^^^^^^^^^^^^^^^^^^
  File "C:\Users\Admin\Nilesh_Projects\CFA\cfa_ai_app\backend\venv\Lib\site-packages\requests\sessions.py", line 589, in request
    resp = self.send(prep, **send_kwargs)
  File "C:\Users\Admin\Nilesh_Projects\CFA\cfa_ai_app\backend\venv\Lib\site-packages\requests\sessions.py", line 703, in send
    r = adapter.send(request, **kwargs)
  File "C:\Users\Admin\Nilesh_Projects\CFA\cfa_ai_app\backend\venv\Lib\site-packages\requests\adapters.py", line 713, in send
    raise ReadTimeout(e, request=request)
requests.exceptions.ReadTimeout: HTTPConnectionPool(host='localhost', port=9000): Read timed out. (read timeout=150)

[2025-07-05 20:18:35] Loaded TALLY_URL: http://localhost:9000
[2025-07-05 20:18:39] Sync Data button clicked.
[2025-07-05 20:18:39] Sending test connection POST to http://localhost:9000
[2025-07-05 20:18:45] ❌ Connection failed: HTTPConnectionPool(host='localhost', port=9000): Max retries exceeded with url: / (Caused by NewConnectionError('<urllib3.connection.HTTPConnection object at 0x0000024B32D54D70>: Failed to establish a new connection: [WinError 10061] No connection could be made because the target machine actively refused it'))
Traceback (most recent call last):
  File "C:\Users\Admin\Nilesh_Projects\CFA\cfa_ai_app\backend\venv\Lib\site-packages\urllib3\connection.py", line 198, in _new_conn
    sock = connection.create_connection(
        (self._dns_host, self.port),
    ...<2 lines>...
        socket_options=self.socket_options,
    )
  File "C:\Users\Admin\Nilesh_Projects\CFA\cfa_ai_app\backend\venv\Lib\site-packages\urllib3\util\connection.py", line 85, in create_connection
    raise err
  File "C:\Users\Admin\Nilesh_Projects\CFA\cfa_ai_app\backend\venv\Lib\site-packages\urllib3\util\connection.py", line 73, in create_connection
    sock.connect(sa)
    ~~~~~~~~~~~~^^^^
ConnectionRefusedError: [WinError 10061] No connection could be made because the target machine actively refused it

The above exception was the direct cause of the following exception:

Traceback (most recent call last):
  File "C:\Users\Admin\Nilesh_Projects\CFA\cfa_ai_app\backend\venv\Lib\site-packages\urllib3\connectionpool.py", line 787, in urlopen
    response = self._make_request(
        conn,
    ...<10 lines>...
        **response_kw,
    )
  File "C:\Users\Admin\Nilesh_Projects\CFA\cfa_ai_app\backend\venv\Lib\site-packages\urllib3\connectionpool.py", line 493, in _make_request
    conn.request(
    ~~~~~~~~~~~~^
        method,
        ^^^^^^^
    ...<6 lines>...
        enforce_content_length=enforce_content_length,
        ^^^^^^^^^^^^^^^^^^^^^^^^^^^^^^^^^^^^^^^^^^^^^^
    )
    ^
  File "C:\Users\Admin\Nilesh_Projects\CFA\cfa_ai_app\backend\venv\Lib\site-packages\urllib3\connection.py", line 494, in request
    self.endheaders()
    ~~~~~~~~~~~~~~~^^
  File "C:\Users\Admin\AppData\Local\Programs\Python\Python313\Lib\http\client.py", line 1333, in endheaders
    self._send_output(message_body, encode_chunked=encode_chunked)
    ~~~~~~~~~~~~~~~~~^^^^^^^^^^^^^^^^^^^^^^^^^^^^^^^^^^^^^^^^^^^^^
  File "C:\Users\Admin\AppData\Local\Programs\Python\Python313\Lib\http\client.py", line 1093, in _send_output
    self.send(msg)
    ~~~~~~~~~^^^^^
  File "C:\Users\Admin\AppData\Local\Programs\Python\Python313\Lib\http\client.py", line 1037, in send
    self.connect()
    ~~~~~~~~~~~~^^
  File "C:\Users\Admin\Nilesh_Projects\CFA\cfa_ai_app\backend\venv\Lib\site-packages\urllib3\connection.py", line 325, in connect
    self.sock = self._new_conn()
                ~~~~~~~~~~~~~~^^
  File "C:\Users\Admin\Nilesh_Projects\CFA\cfa_ai_app\backend\venv\Lib\site-packages\urllib3\connection.py", line 213, in _new_conn
    raise NewConnectionError(
        self, f"Failed to establish a new connection: {e}"
    ) from e
urllib3.exceptions.NewConnectionError: <urllib3.connection.HTTPConnection object at 0x0000024B32D54D70>: Failed to establish a new connection: [WinError 10061] No connection could be made because the target machine actively refused it

The above exception was the direct cause of the following exception:

Traceback (most recent call last):
  File "C:\Users\Admin\Nilesh_Projects\CFA\cfa_ai_app\backend\venv\Lib\site-packages\requests\adapters.py", line 667, in send
    resp = conn.urlopen(
        method=request.method,
    ...<9 lines>...
        chunked=chunked,
    )
  File "C:\Users\Admin\Nilesh_Projects\CFA\cfa_ai_app\backend\venv\Lib\site-packages\urllib3\connectionpool.py", line 841, in urlopen
    retries = retries.increment(
        method, url, error=new_e, _pool=self, _stacktrace=sys.exc_info()[2]
    )
  File "C:\Users\Admin\Nilesh_Projects\CFA\cfa_ai_app\backend\venv\Lib\site-packages\urllib3\util\retry.py", line 519, in increment
    raise MaxRetryError(_pool, url, reason) from reason  # type: ignore[arg-type]
    ^^^^^^^^^^^^^^^^^^^^^^^^^^^^^^^^^^^^^^^^^^^^^^^^^^^
urllib3.exceptions.MaxRetryError: HTTPConnectionPool(host='localhost', port=9000): Max retries exceeded with url: / (Caused by NewConnectionError('<urllib3.connection.HTTPConnection object at 0x0000024B32D54D70>: Failed to establish a new connection: [WinError 10061] No connection could be made because the target machine actively refused it'))

During handling of the above exception, another exception occurred:

Traceback (most recent call last):
  File "C:\Users\Admin\Nilesh_Projects\CFA\cfa_ai_app\Desktop_tally_sync-agent\tally_connector.py", line 50, in test_tally_connection
    response = requests.post(TALLY_URL, data=test_request, timeout=150)  # 2 minutes
  File "C:\Users\Admin\Nilesh_Projects\CFA\cfa_ai_app\backend\venv\Lib\site-packages\requests\api.py", line 115, in post
    return request("post", url, data=data, json=json, **kwargs)
  File "C:\Users\Admin\Nilesh_Projects\CFA\cfa_ai_app\backend\venv\Lib\site-packages\requests\api.py", line 59, in request
    return session.request(method=method, url=url, **kwargs)
           ~~~~~~~~~~~~~~~^^^^^^^^^^^^^^^^^^^^^^^^^^^^^^^^^^
  File "C:\Users\Admin\Nilesh_Projects\CFA\cfa_ai_app\backend\venv\Lib\site-packages\requests\sessions.py", line 589, in request
    resp = self.send(prep, **send_kwargs)
  File "C:\Users\Admin\Nilesh_Projects\CFA\cfa_ai_app\backend\venv\Lib\site-packages\requests\sessions.py", line 703, in send
    r = adapter.send(request, **kwargs)
  File "C:\Users\Admin\Nilesh_Projects\CFA\cfa_ai_app\backend\venv\Lib\site-packages\requests\adapters.py", line 700, in send
    raise ConnectionError(e, request=request)
requests.exceptions.ConnectionError: HTTPConnectionPool(host='localhost', port=9000): Max retries exceeded with url: / (Caused by NewConnectionError('<urllib3.connection.HTTPConnection object at 0x0000024B32D54D70>: Failed to establish a new connection: [WinError 10061] No connection could be made because the target machine actively refused it'))

[2025-07-05 20:18:47] Tally not connected. Sync aborted.
[2025-07-05 20:21:36] Sync Data button clicked.
[2025-07-05 20:21:36] Sending test connection POST to http://localhost:9000
[2025-07-05 20:21:44] ❌ Connection failed: ('Connection aborted.', ConnectionResetError(10054, 'An existing connection was forcibly closed by the remote host', None, 10054, None))
Traceback (most recent call last):
  File "C:\Users\Admin\Nilesh_Projects\CFA\cfa_ai_app\backend\venv\Lib\site-packages\urllib3\connectionpool.py", line 787, in urlopen
    response = self._make_request(
        conn,
    ...<10 lines>...
        **response_kw,
    )
  File "C:\Users\Admin\Nilesh_Projects\CFA\cfa_ai_app\backend\venv\Lib\site-packages\urllib3\connectionpool.py", line 534, in _make_request
    response = conn.getresponse()
  File "C:\Users\Admin\Nilesh_Projects\CFA\cfa_ai_app\backend\venv\Lib\site-packages\urllib3\connection.py", line 565, in getresponse
    httplib_response = super().getresponse()
  File "C:\Users\Admin\AppData\Local\Programs\Python\Python313\Lib\http\client.py", line 1430, in getresponse
    response.begin()
    ~~~~~~~~~~~~~~^^
  File "C:\Users\Admin\AppData\Local\Programs\Python\Python313\Lib\http\client.py", line 331, in begin
    version, status, reason = self._read_status()
                              ~~~~~~~~~~~~~~~~~^^
  File "C:\Users\Admin\AppData\Local\Programs\Python\Python313\Lib\http\client.py", line 292, in _read_status
    line = str(self.fp.readline(_MAXLINE + 1), "iso-8859-1")
               ~~~~~~~~~~~~~~~~^^^^^^^^^^^^^^
  File "C:\Users\Admin\AppData\Local\Programs\Python\Python313\Lib\socket.py", line 719, in readinto
    return self._sock.recv_into(b)
           ~~~~~~~~~~~~~~~~~~~~^^^
ConnectionResetError: [WinError 10054] An existing connection was forcibly closed by the remote host

During handling of the above exception, another exception occurred:

Traceback (most recent call last):
  File "C:\Users\Admin\Nilesh_Projects\CFA\cfa_ai_app\backend\venv\Lib\site-packages\requests\adapters.py", line 667, in send
    resp = conn.urlopen(
        method=request.method,
    ...<9 lines>...
        chunked=chunked,
    )
  File "C:\Users\Admin\Nilesh_Projects\CFA\cfa_ai_app\backend\venv\Lib\site-packages\urllib3\connectionpool.py", line 841, in urlopen
    retries = retries.increment(
        method, url, error=new_e, _pool=self, _stacktrace=sys.exc_info()[2]
    )
  File "C:\Users\Admin\Nilesh_Projects\CFA\cfa_ai_app\backend\venv\Lib\site-packages\urllib3\util\retry.py", line 474, in increment
    raise reraise(type(error), error, _stacktrace)
          ~~~~~~~^^^^^^^^^^^^^^^^^^^^^^^^^^^^^^^^^
  File "C:\Users\Admin\Nilesh_Projects\CFA\cfa_ai_app\backend\venv\Lib\site-packages\urllib3\util\util.py", line 38, in reraise
    raise value.with_traceback(tb)
  File "C:\Users\Admin\Nilesh_Projects\CFA\cfa_ai_app\backend\venv\Lib\site-packages\urllib3\connectionpool.py", line 787, in urlopen
    response = self._make_request(
        conn,
    ...<10 lines>...
        **response_kw,
    )
  File "C:\Users\Admin\Nilesh_Projects\CFA\cfa_ai_app\backend\venv\Lib\site-packages\urllib3\connectionpool.py", line 534, in _make_request
    response = conn.getresponse()
  File "C:\Users\Admin\Nilesh_Projects\CFA\cfa_ai_app\backend\venv\Lib\site-packages\urllib3\connection.py", line 565, in getresponse
    httplib_response = super().getresponse()
  File "C:\Users\Admin\AppData\Local\Programs\Python\Python313\Lib\http\client.py", line 1430, in getresponse
    response.begin()
    ~~~~~~~~~~~~~~^^
  File "C:\Users\Admin\AppData\Local\Programs\Python\Python313\Lib\http\client.py", line 331, in begin
    version, status, reason = self._read_status()
                              ~~~~~~~~~~~~~~~~~^^
  File "C:\Users\Admin\AppData\Local\Programs\Python\Python313\Lib\http\client.py", line 292, in _read_status
    line = str(self.fp.readline(_MAXLINE + 1), "iso-8859-1")
               ~~~~~~~~~~~~~~~~^^^^^^^^^^^^^^
  File "C:\Users\Admin\AppData\Local\Programs\Python\Python313\Lib\socket.py", line 719, in readinto
    return self._sock.recv_into(b)
           ~~~~~~~~~~~~~~~~~~~~^^^
urllib3.exceptions.ProtocolError: ('Connection aborted.', ConnectionResetError(10054, 'An existing connection was forcibly closed by the remote host', None, 10054, None))

During handling of the above exception, another exception occurred:

Traceback (most recent call last):
  File "C:\Users\Admin\Nilesh_Projects\CFA\cfa_ai_app\Desktop_tally_sync-agent\tally_connector.py", line 50, in test_tally_connection
    response = requests.post(TALLY_URL, data=test_request, timeout=150)  # 2 minutes
  File "C:\Users\Admin\Nilesh_Projects\CFA\cfa_ai_app\backend\venv\Lib\site-packages\requests\api.py", line 115, in post
    return request("post", url, data=data, json=json, **kwargs)
  File "C:\Users\Admin\Nilesh_Projects\CFA\cfa_ai_app\backend\venv\Lib\site-packages\requests\api.py", line 59, in request
    return session.request(method=method, url=url, **kwargs)
           ~~~~~~~~~~~~~~~^^^^^^^^^^^^^^^^^^^^^^^^^^^^^^^^^^
  File "C:\Users\Admin\Nilesh_Projects\CFA\cfa_ai_app\backend\venv\Lib\site-packages\requests\sessions.py", line 589, in request
    resp = self.send(prep, **send_kwargs)
  File "C:\Users\Admin\Nilesh_Projects\CFA\cfa_ai_app\backend\venv\Lib\site-packages\requests\sessions.py", line 703, in send
    r = adapter.send(request, **kwargs)
  File "C:\Users\Admin\Nilesh_Projects\CFA\cfa_ai_app\backend\venv\Lib\site-packages\requests\adapters.py", line 682, in send
    raise ConnectionError(err, request=request)
requests.exceptions.ConnectionError: ('Connection aborted.', ConnectionResetError(10054, 'An existing connection was forcibly closed by the remote host', None, 10054, None))

[2025-07-05 20:21:45] Tally not connected. Sync aborted.
